Workbook

Sheet CAPA
A1: #VALUE! | C1: #VALUE! | E1: CONSÓRIO CONSTRUTOR BR-381 | I1: Nº MEDIÇÃO | K1: TIPO
I2: 3 | K2: FINAL
A4: CONTRATO: | B4: 381/188/2025 | D4: EMPRESA: | E4: CONSÓRCIO CONSTRUTOR BR-381 | H4: STATUS CONTRATUAL
A5: OBJETO: | B5: RECOMPOSIÇÃO DE TALUDES - SINISTRO 297+500 - OESTE | H5: R$ CONTRATUAL: | J5: =PQ!E140 -> 6891850.4 | L5: =SUM(L12:L13,L17,L22,L27:L28) -> 0.98371424
A6: TRECHO: | B6: GOV. VALADARES A CAETÉ
A7: RODOVIA: | B7: BR-381 | D7: EXTENSÃO: | H7: R$ MEDIÇÃO: | J7: =SUM(G12,G13,G17,G22,G27,G28) -> 2352439.6
A8: MEDIÇÃO: | B8: =I2 -> 3 | D8: PERÍODO: | E8: 24/09/2025 A 23/10/2025
A10: GRUPO DE SERVIÇOS | E10: ACUMULADO ANTERIOR | G10: =_xlfn.CONCAT(TEXT(I2,"00"),"ª MEDIÇÃO"," ",K2) -> 03ª MEDIÇÃO FINAL | I10: ACUMULADO ATUAL | K10: MEDIÇÃO ATUAL | L10: ACUMULADO
A12: =PQ!B13 -> A. | B12: =UPPER(VLOOKUP(A12,RESUMO!C:D,2,FALSE)) -> CUSTOS INDIRETOS | E12: =VLOOKUP($A12,PQ!$B:$R,9,FALSE)*1.182 -> 650700.05 | G12: =VLOOKUP($A12,PQ!$B:$R,11,FALSE)*1.182 -> 0 | I12: =VLOOKUP($A12,PQ!$B:$R,13,FALSE)*1.182 -> 650700.05 | K12: =IF(G12/$J$5=0,"",G12/$J$5) | L12: =IF(I12/$J$5=0,"",I12/$J$5) -> 0.09441587
A13: =PQ!B17 -> B. | B13: =UPPER(VLOOKUP(A13,RESUMO!C:D,2,FALSE)) -> ESTABILIZAÇÃO DE TALUDE | E13: =VLOOKUP($A13,PQ!$B:$R,9,FALSE)*1.182 -> 2361880.2 | G13: =VLOOKUP($A13,PQ!$B:$R,11,FALSE)*1.182 -> 2211056 | I13: =VLOOKUP($A13,PQ!$B:$R,13,FALSE)*1.182 -> 4572936.2 | K13: =IF(G13/$J$5=0,"",G13/$J$5) -> 0.32082182 | L13: =IF(I13/$J$5=0,"",I13/$J$5) -> 0.66352807
A14: =PQ!B18 -> B.1 | B14: =UPPER(VLOOKUP(A14,RESUMO!C:D,2,FALSE)) -> TERRAPLENAGEM | E14: =VLOOKUP($A14,PQ!$B:$R,9,FALSE)*1.182 -> 2085619.7 | G14: =VLOOKUP($A14,PQ!$B:$R,11,FALSE)*1.182 -> 1036960.7 | I14: =VLOOKUP($A14,PQ!$B:$R,13,FALSE)*1.182 -> 3122580.4 | K14: =IF(G14/$J$5=0,"",G14/$J$5) -> 0.15046187 | L14: =IF(I14/$J$5=0,"",I14/$J$5) -> 0.45308302
A15: =PQ!B28 -> B.2 | B15: =UPPER(VLOOKUP(A15,RESUMO!C:D,2,FALSE)) -> DRENAGEM E OACS | E15: =VLOOKUP($A15,PQ!$B:$R,9,FALSE)*1.182 -> 0 | G15: =VLOOKUP($A15,PQ!$B:$R,11,FALSE)*1.182 -> 439810.25 | I15: =VLOOKUP($A15,PQ!$B:$R,13,FALSE)*1.182 -> 439810.25 | K15: =IF(G15/$J$5=0,"",G15/$J$5) -> 0.063815989 | L15: =IF(I15/$J$5=0,"",I15/$J$5) -> 0.063815989
A16: =PQ!B38 -> B.3 | B16: =UPPER(VLOOKUP(A16,RESUMO!C:D,2,FALSE)) -> REVESTIMENTO VEGETAL | E16: =VLOOKUP($A16,PQ!$B:$R,9,FALSE)*1.182 -> 276260.49 | G16: =VLOOKUP($A16,PQ!$B:$R,11,FALSE)*1.182 -> 734285.08 | I16: =VLOOKUP($A16,PQ!$B:$R,13,FALSE)*1.182 -> 1010545.6 | K16: =IF(G16/$J$5=0,"",G16/$J$5) -> 0.10654397 | L16: =IF(I16/$J$5=0,"",I16/$J$5) -> 0.14662906
A17: =PQ!B41 -> C. | B17: =UPPER(VLOOKUP(A17,RESUMO!C:D,2,FALSE)) -> IMPLANTAÇÃO DE DESVIO 1 - KM 303+450 - LESTE | E17: =VLOOKUP($A17,PQ!$B:$R,9,FALSE)*1.182 -> 917970.25 | G17: =VLOOKUP($A17,PQ!$B:$R,11,FALSE)*1.182 -> 31336.711 | I17: =VLOOKUP($A17,PQ!$B:$R,13,FALSE)*1.182 -> 949306.97 | K17: =IF(G17/$J$5=0,"",G17/$J$5) -> 0.0045469227 | L17: =IF(I17/$J$5=0,"",I17/$J$5) -> 0.13774341
A18: =PQ!B42 -> C.1 | B18: =UPPER(VLOOKUP(A18,RESUMO!C:D,2,FALSE)) -> TERRAPLENAGEM | E18: =VLOOKUP($A18,PQ!$B:$R,9,FALSE)*1.182 -> 29257.461 | G18: =VLOOKUP($A18,PQ!$B:$R,11,FALSE)*1.182 -> 0 | I18: =VLOOKUP($A18,PQ!$B:$R,13,FALSE)*1.182 -> 29257.461 | K18: =IF(G18/$J$5=0,"",G18/$J$5) | L18: =IF(I18/$J$5=0,"",I18/$J$5) -> 0.0042452257
A19: =PQ!B48 -> C.2 | B19: =UPPER(VLOOKUP(A19,RESUMO!C:D,2,FALSE)) -> PAVIMENTAÇÃO | E19: =VLOOKUP($A19,PQ!$B:$R,9,FALSE)*1.182 -> 510414.79 | G19: =VLOOKUP($A19,PQ!$B:$R,11,FALSE)*1.182 -> 0 | I19: =VLOOKUP($A19,PQ!$B:$R,13,FALSE)*1.182 -> 510414.79 | K19: =IF(G19/$J$5=0,"",G19/$J$5) | L19: =IF(I19/$J$5=0,"",I19/$J$5) -> 0.074060631
A20: =PQ!B55 -> C.3 | B20: =UPPER(VLOOKUP(A20,RESUMO!C:D,2,FALSE)) -> MATERIAL BETUMINOSO E TRANSPORTES | E20: =VLOOKUP($A20,PQ!$B:$R,9,FALSE)*1.182 -> 378298 | G20: =VLOOKUP($A20,PQ!$B:$R,11,FALSE)*1.182 -> 0 | I20: =VLOOKUP($A20,PQ!$B:$R,13,FALSE)*1.182 -> 378298 | K20: =IF(G20/$J$5=0,"",G20/$J$5) | L20: =IF(I20/$J$5=0,"",I20/$J$5) -> 0.054890628
A21: =PQ!B62 -> C.4 | B21: =UPPER(VLOOKUP(A21,RESUMO!C:D,2,FALSE)) -> DRENAGEM E OACS | E21: =VLOOKUP($A21,PQ!$B:$R,9,FALSE)*1.182 -> 0 | G21: =VLOOKUP($A21,PQ!$B:$R,11,FALSE)*1.182 -> 31336.711 | I21: =VLOOKUP($A21,PQ!$B:$R,13,FALSE)*1.182 -> 31336.711 | K21: =IF(G21/$J$5=0,"",G21/$J$5) -> 0.0045469227 | L21: =IF(I21/$J$5=0,"",I21/$J$5) -> 0.0045469227
A22: =PQ!B68 -> D. | B22: =UPPER(VLOOKUP(A22,RESUMO!C:D,2,FALSE)) -> IMPLANTAÇÃO DE DESVIOS 2 E 3 | E22: =VLOOKUP($A22,PQ!$B:$R,9,FALSE)*1.182 -> 473829.21 | G22: =VLOOKUP($A22,PQ!$B:$R,11,FALSE)*1.182 -> -11511.412 | I22: =VLOOKUP($A22,PQ!$B:$R,13,FALSE)*1.182 -> 462317.8 | K22: =IF(G22/$J$5=0,"",G22/$J$5) -> -0.0016702934 | L22: =IF(I22/$J$5=0,"",I22/$J$5) -> 0.06708181
A23: =PQ!B69 -> D.1 | B23: =UPPER(VLOOKUP(A23,RESUMO!C:D,2,FALSE)) -> TERRAPLENAGEM | E23: =VLOOKUP($A23,PQ!$B:$R,9,FALSE)*1.182 -> 29346.462 | G23: =VLOOKUP($A23,PQ!$B:$R,11,FALSE)*1.182 -> -21369.765 | I23: =VLOOKUP($A23,PQ!$B:$R,13,FALSE)*1.182 -> 7976.6974 | K23: =IF(G23/$J$5=0,"",G23/$J$5) -> -0.0031007297 | L23: =IF(I23/$J$5=0,"",I23/$J$5) -> 0.0011574101
A24: =PQ!B75 -> D.2 | B24: =UPPER(VLOOKUP(A24,RESUMO!C:D,2,FALSE)) -> PAVIMENTO | E24: =VLOOKUP($A24,PQ!$B:$R,9,FALSE)*1.182 -> 254629.92 | G24: =VLOOKUP($A24,PQ!$B:$R,11,FALSE)*1.182 -> 0 | I24: =VLOOKUP($A24,PQ!$B:$R,13,FALSE)*1.182 -> 254629.92 | K24: =IF(G24/$J$5=0,"",G24/$J$5) | L24: =IF(I24/$J$5=0,"",I24/$J$5) -> 0.036946525
A25: =PQ!B83 -> D.3 | B25: =UPPER(VLOOKUP(A25,RESUMO!C:D,2,FALSE)) -> MATERIAL BETUMINOSO E TRANSPORTES | E25: =VLOOKUP($A25,PQ!$B:$R,9,FALSE)*1.182 -> 189852.83 | G25: =VLOOKUP($A25,PQ!$B:$R,11,FALSE)*1.182 -> 0 | I25: =VLOOKUP($A25,PQ!$B:$R,13,FALSE)*1.182 -> 189852.83 | K25: =IF(G25/$J$5=0,"",G25/$J$5) | L25: =IF(I25/$J$5=0,"",I25/$J$5) -> 0.027547439
A26: =PQ!B90 -> D.4 | B26: =UPPER(VLOOKUP(A26,RESUMO!C:D,2,FALSE)) -> DRENAGEM E OACS | E26: =VLOOKUP($A26,PQ!$B:$R,9,FALSE)*1.182 -> 0 | G26: =VLOOKUP($A26,PQ!$B:$R,11,FALSE)*1.182 -> 9858.3528 | I26: =VLOOKUP($A26,PQ!$B:$R,13,FALSE)*1.182 -> 9858.3528 | K26: =IF(G26/$J$5=0,"",G26/$J$5) -> 0.0014304363 | L26: =IF(I26/$J$5=0,"",I26/$J$5) -> 0.0014304363
A27: =PQ!B93 -> E. | B27: =UPPER(VLOOKUP(A27,RESUMO!C:D,2,FALSE)) -> SINALIZAÇÃO HORIZONTAL, VERTICAL E ELEMENTOS DE PROTEÇÃO E SEGURANÇA | E27: =VLOOKUP($A27,PQ!$B:$R,9,FALSE)*1.182 -> 22792.053 | G27: =VLOOKUP($A27,PQ!$B:$R,11,FALSE)*1.182 -> 0 | I27: =VLOOKUP($A27,PQ!$B:$R,13,FALSE)*1.182 -> 22792.053 | K27: =IF(G27/$J$5=0,"",G27/$J$5) | L27: =IF(I27/$J$5=0,"",I27/$J$5) -> 0.003307102
A28: =PQ!B95 -> F. | B28: =UPPER(VLOOKUP(A28,RESUMO!C:D,2,FALSE)) -> MÃO DE OBRA E EQUIPAMENTOS | E28: =VLOOKUP($A28,PQ!$B:$R,9,FALSE)*1.182 -> 0 | G28: =VLOOKUP($A28,PQ!$B:$R,11,FALSE)*1.182 -> 121558.3 | I28: =VLOOKUP($A28,PQ!$B:$R,13,FALSE)*1.182 -> 121558.3 | K28: =IF(G28/$J$5=0,"",G28/$J$5) -> 0.017637978 | L28: =IF(I28/$J$5=0,"",I28/$J$5) -> 0.017637978
A29: =PQ!B96 -> F.1 | B29: =UPPER(VLOOKUP(A29,RESUMO!C:D,2,FALSE)) -> MÃO DE OBRA | E29: =VLOOKUP($A29,PQ!$B:$R,9,FALSE)*1.182 -> 0 | G29: =VLOOKUP($A29,PQ!$B:$R,11,FALSE)*1.182 -> 15329.925 | I29: =VLOOKUP($A29,PQ!$B:$R,13,FALSE)*1.182 -> 15329.925 | K29: =IF(G29/$J$5=0,"",G29/$J$5) -> 0.0022243555 | L29: =IF(I29/$J$5=0,"",I29/$J$5) -> 0.0022243555
A30: =PQ!B100 -> F.2 | B30: =UPPER(VLOOKUP(A30,RESUMO!C:D,2,FALSE)) -> EQUIPAMENTOS | E30: =VLOOKUP($A30,PQ!$B:$R,9,FALSE)*1.182 -> 0 | G30: =VLOOKUP($A30,PQ!$B:$R,11,FALSE)*1.182 -> 106228.38 | I30: =VLOOKUP($A30,PQ!$B:$R,13,FALSE)*1.182 -> 106228.38 | K30: =IF(G30/$J$5=0,"",G30/$J$5) -> 0.015413622 | L30: =IF(I30/$J$5=0,"",I30/$J$5) -> 0.015413622

Sheet PQ
B2: BOLETIM DE MEDIÇÃO DE SERVIÇOS - BMS | I2: CONTRATO | L2: PERIODO MEDIÇÃO | N2: MEDIÇÃO | P2: Nº DO BMS | T2: Rev. 01
I3: 381/188/2025 | P3: MED. 03 - rev03 | T3: Base: Jan/25
I4: VIGÊNCIA | L4: INÍCIO: | M4: 45924 | P4: DATA DE EMISSÃO
L5: FINAL: | M5: 45953 | P5: 45978
B6: EMPRESA | C6: CONSÓRCIO CONSTRUTOR BR-381 | I6: OBJETO CONTRATUAL | P6: CENTRO DE CUSTO
B7: ENDEREÇO | C7: R PROJETADA 30, 386, PEDRA FURADA | I7: RECOMPOSIÇÃO DE TALUDES - SINISTRO 297+500 - OESTE
B8: CIDADE/UF: | C8: NOVA ERA/MG
B9: TELEFONE: | C9: (31) 9 9659-1026 | D9: E-MAIL: | E9: ygor.bastos@consorcio381.com.br
B10: ITEM | C10: DESCRIÇÃO | D10: CENTRO DE CUSTO | E10: BASES CONTRATUAIS - rev01 | I10: REALIZADO | P10: A REALIZAR | T10: BASES CONTRATUAIS
E11: UNID. | F11: P. UNITÁRIO (R$ / UNID.) | G11: QTDE | H11: VALOR TOTAL | I11: ACUMULADO ANTERIOR | K11: PERÍODO | M11: ACUMULADO ATUAL | P11: SALDO | T11: UNID. | U11: P. UNITÁRIO (R$ / UNID.) | V11: QTDE | W11: VALOR TOTAL
I12: QTDE | J12: VALOR | K12: QTDE | L12: VALOR | M12: QTDE | N12: VALOR | O12: % | P12: QTDE | Q12: VALOR | R12: %
B13: A. | C13: Custos Indiretos | H13: =SUM(H14:H16) -> 550507.66 | J13: =SUM(J14:J16) -> 550507.66 | L13: =SUM(L14:L16) -> 0 | N13: =SUM(N14:N16) -> 550507.66 | Q13: =SUM(Q14:Q16) -> 0 | W13: =SUM(W14:W16) -> 550507.67
B14: A.1 | C14: Mobilização e desmobilização | E14: vb. | F14: 22570.81 | G14: 1 | H14: =F14*G14 -> 22570.81 | I14: =RESUMO!H9 -> 1 | J14: =RESUMO!M9 -> 22570.81 | K14: =RESUMO!I9 -> 0 | L14: =RESUMO!N9 -> 0 | M14: =RESUMO!J9 -> 1 | N14: =RESUMO!O9 -> 22570.81 | O14: =RESUMO!R9 -> 1 | P14: =RESUMO!K9 -> 0 | Q14: =RESUMO!P9 -> 0 | R14: =1-O14 -> 0 | T14: vb. | U14: 22570.814 | V14: 1 | W14: =V14*U14 -> 22570.814
B15: A.2 | C15: Sinalização e desvio de tráfego | E15: vb. | F15: 45141.63 | G15: 1 | H15: =F15*G15 -> 45141.63 | I15: =RESUMO!H10 -> 1 | J15: =RESUMO!M10 -> 45141.63 | K15: =RESUMO!I10 -> 0 | L15: =RESUMO!N10 -> 0 | M15: =RESUMO!J10 -> 1 | N15: =RESUMO!O10 -> 45141.63 | O15: =RESUMO!R10 -> 1 | P15: =RESUMO!K10 -> 0 | Q15: =RESUMO!P10 -> 0 | R15: =1-O15 -> 0 | T15: vb. | U15: 45141.629 | V15: 1 | W15: =V15*U15 -> 45141.629
B16: A.3 | C16: Administração local | E16: vb. | F16: 482795.22 | G16: 1 | H16: =F16*G16 -> 482795.22 | I16: =RESUMO!H11 -> 1 | J16: =RESUMO!M11 -> 482795.22 | K16: =RESUMO!I11 -> 0 | L16: =RESUMO!N11 -> 0 | M16: =RESUMO!J11 -> 1 | N16: =RESUMO!O11 -> 482795.22 | O16: =RESUMO!R11 -> 1 | P16: =RESUMO!K11 -> 0 | Q16: =RESUMO!P11 -> 0 | R16: =1-O16 -> 0 | T16: vb. | U16: 482795.22 | V16: 1 | W16: =V16*U16 -> 482795.22
B17: B. | C17: Estabilização de Talude | H17: =SUBTOTAL(9,H18:H40) -> 3675277.4 | J17: =SUBTOTAL(9,J18:J40) -> 1998206.6 | L17: =SUBTOTAL(9,L18:L40) -> 1870605.8 | N17: =SUBTOTAL(9,N18:N40) -> 3868812.4 | Q17: =SUBTOTAL(9,Q18:Q40) -> -193535.02 | W17: =SUBTOTAL(9,W18:W39) -> 3578784
B18: B.1 | C18: Terraplenagem | H18: =SUBTOTAL(9,H19:H27) -> 2726353.3 | J18: =SUBTOTAL(9,J19:J27) -> 1764483.7 | L18: =SUBTOTAL(9,L19:L27) -> 877293.31 | N18: =SUBTOTAL(9,N19:N27) -> 2641777 | Q18: =SUBTOTAL(9,Q19:Q27) -> 84576.263 | W18: =SUBTOTAL(9,W19:W23) -> 2838512.9
B19: B.1.1 | C19: Escavação, carga e transporte de material de 1ª categoria - DMT de 800 a 1.000 m - caminho de serviço pavimentado - com escavadeira e caminhão basculante de 14 m³ | E19: m³ | F19: 0 | G19: 0 | H19: =F19*G19 -> 0 | I19: =RESUMO!H14 -> 0 | J19: =RESUMO!M14 -> 0 | K19: =RESUMO!I14 -> 0 | L19: =RESUMO!N14 -> 0 | M19: =RESUMO!J14 -> 0 | N19: =RESUMO!O14 -> 0 | O19: =RESUMO!R14 -> 0 | P19: =RESUMO!K14 -> 0 | Q19: =RESUMO!P14 -> 0 | R19: =1-O19 -> 1 | T19: m³ | U19: 10.09 | V19: 25000 | W19: =ROUND(V19*U19,2) -> 252250
B20: B.1.2 | C20: Escavação e carga de material de 1ª categoria - DMT acima de 3.000 m | E20: m³ | F20: 15.86326 | G20: 72616.71 | H20: =F20*G20 -> 1151937.7 | I20: =RESUMO!H15 -> 62616.71 | J20: =RESUMO!M15 -> 993305.14 | K20: =RESUMO!I15 -> 6145.816 | L20: =RESUMO!N15 -> 97492.676 | M20: =RESUMO!J15 -> 68762.526 | N20: =RESUMO!O15 -> 1090797.8 | O20: =RESUMO!R15 -> 0.94692428 | P20: =RESUMO!K15 -> 3854.184 | Q20: =RESUMO!P15 -> 61139.922 | R20: =1-O20 -> 0.053075718 | T20: m³ | U20: 15.86326 | V20: 94031.76 | W20: =ROUND(V20*U20,2) -> 1491650.2
B21: B.1.3 | C21: Transporte com caminhão basculante de 10 m³ - rodovia pavimentada (DMT 5 Km) | E21: T x Km | F21: 1.0278799 | G21: 543194.94 | H21: =F21*G21 -> 558339.16 | I21: =RESUMO!H16 -> 483457.86 | J21: =RESUMO!M16 -> 496936.61 | K21: =RESUMO!I16 -> 47451.28 | L21: =RESUMO!N16 -> 48774.217 | M21: =RESUMO!J16 -> 530909.14 | N21: =RESUMO!O16 -> 545710.83 | O21: =RESUMO!R16 -> 0.97738233 | P21: =RESUMO!K16 -> 12285.803 | Q21: =RESUMO!P16 -> 12628.33 | R21: =1-O21 -> 0.022617668 | T21: T x Km | U21: 1.0278799 | V21: 752254.08 | W21: =ROUND(V21*U21,2) -> 773226.85
B22: B.1.4 | C22: Regularização de bota-fora com espalhamento e execução de hidrossemeadura | E22: m³ | F22: 0 | G22: 0 | H22: =F22*G22 -> 0 | I22: =RESUMO!H17 -> 0 | J22: =RESUMO!M17 -> 0 | K22: =RESUMO!I17 -> 0 | L22: =RESUMO!N17 -> 0 | M22: =RESUMO!J17 -> 0 | N22: =RESUMO!O17 -> 0 | O22: =RESUMO!R17 -> 0 | P22: =RESUMO!K17 -> 0 | Q22: =RESUMO!P17 -> 0 | R22: =1-O22 -> 1 | T22: m³ | U22: 2.7 | V22: 119031.76 | W22: =ROUND(V22*U22,2) -> 321385.75
B23: B.1.5 | C23: Royaltie de bota-fora | E23: m³ | F23: 0 | G23: 0 | H23: =F23*G23 -> 0 | I23: =RESUMO!H18 -> 0 | J23: =RESUMO!M18 -> 0 | K23: =RESUMO!I18 -> 0 | L23: =RESUMO!N18 -> 0 | M23: =RESUMO!J18 -> 0 | N23: =RESUMO!O18 -> 0 | O23: =RESUMO!R18 -> 0 | P23: =RESUMO!K18 -> 0 | Q23: =RESUMO!P18 -> 0 | R23: =1-O23 -> 1
B24: B.1.6 | C24: Desmatamento, destocamento, limpeza de área e estocagem do material de limpeza com árvores de diâmetro até 0,15 m | E24: m² | F24: 0.85999993 | G24: 23377.56 | H24: =F24*G24 -> 20104.7 | I24: =RESUMO!H19 -> 0 | J24: =RESUMO!M19 -> 0 | K24: =RESUMO!I19 -> 21252.33 | L24: =RESUMO!N19 -> 18277.002 | M24: =RESUMO!J19 -> 21252.33 | N24: =RESUMO!O19 -> 18277.002 | O24: =RESUMO!R19 -> 0.90909103 | P24: =RESUMO!K19 -> 2125.23 | Q24: =RESUMO!P19 -> 1827.6977 | R24: =1-O24 -> 0.090908974
B25: B.1.7 | C25: Escavação, carga e transporte de material de 1ª categoria - DMT de 1.400 a 1.600 m - caminho de serviço pavimentado - com escavadeira e caminhão basculante de 14 m³ | E25: m³ | F25: 12.629999 | G25: 55083.7 | H25: =F25*G25 -> 695707.09 | I25: =RESUMO!H20 -> 0 | J25: =RESUMO!M20 -> 0 | K25: =RESUMO!I20 -> 55083.697 | L25: =RESUMO!N20 -> 695707.05 | M25: =RESUMO!J20 -> 55083.697 | N25: =RESUMO!O20 -> 695707.05 | O25: =RESUMO!R20 -> 0.99999995 | P25: =RESUMO!K20 -> 0.003 | Q25: =RESUMO!P20 -> 0.037889998 | R25: =1-O25 -> 5.4462572e-08
B26: B.1.8 | C26: Escavação e carga de material de 2ª categoria - DMT acima de 3.000 m | E26: m³ | F26: 19.519859 | G26: 139.48 | H26: =F26*G26 -> 2722.63 | I26: =RESUMO!H21 -> 0 | J26: =RESUMO!M21 -> 0 | K26: =RESUMO!I21 -> 139.479 | L26: =RESUMO!N21 -> 2722.6105 | M26: =RESUMO!J21 -> 139.479 | N26: =RESUMO!O21 -> 2722.6105 | O26: =RESUMO!R21 -> 0.99999283 | P26: =RESUMO!K21 -> 0.001 | Q26: =RESUMO!P21 -> 0.019519859 | R26: =1-O26 -> 7.1694867e-06
B27: B.1.9 | C27: Regularização de bota-fora | E27: m³ | F27: 2.33 | G27: 127700.41 | H27: =F27*G27 -> 297541.95 | I27: =RESUMO!H22 -> 117700.41 | J27: =RESUMO!M22 -> 274241.94 | K27: =RESUMO!I22 -> 6145.816 | L27: =RESUMO!N22 -> 14319.751 | M27: =RESUMO!J22 -> 123846.22 | N27: =RESUMO!O22 -> 288561.69 | O27: =RESUMO!R22 -> 0.96981852 | P27: =RESUMO!K22 -> 3854.187 | Q27: =RESUMO!P22 -> 8980.2556 | R27: =1-O27 -> 0.030181477
B28: B.2 | C28: Drenagem e OACs | H28: =SUBTOTAL(9,H29:H37) -> 549924.1 | J28: =SUBTOTAL(9,J29:J37) -> 0 | L28: =SUBTOTAL(9,L29:L37) -> 372089.89 | N28: =SUBTOTAL(9,N29:N37) -> 372089.89 | Q28: =SUBTOTAL(9,Q29:Q37) -> 177834.21 | W28: =SUBTOTAL(9,W29:W33) -> 335471.11
B29: B.2.1 | C29: Demolição de dispositivos de drenagem | E29: m³ | F29: 0 | G29: 0 | H29: =F29*G29 -> 0 | I29: =RESUMO!H24 -> 0 | J29: =RESUMO!M24 -> 0 | K29: =RESUMO!I24 -> 0 | L29: =RESUMO!N24 -> 0 | M29: =RESUMO!J24 -> 0 | N29: =RESUMO!O24 -> 0 | O29: =RESUMO!R24 -> 0 | P29: =RESUMO!K24 -> 0 | Q29: =RESUMO!P24 -> 0 | R29: =1-O29 -> 1 | T29: m³ | U29: 488.98472 | V29: 102 | W29: =ROUND(V29*U29,2) -> 49876.44
B30: B.2.2 | C30: Sarjeta triangular de concreto - STC 150-30 - escavação mecânica - areia e brita comerciais | E30: m | F30: 0 | G30: 0 | H30: =F30*G30 -> 0 | I30: =RESUMO!H25 -> 0 | J30: =RESUMO!M25 -> 0 | K30: =RESUMO!I25 -> 0 | L30: =RESUMO!N25 -> 0 | M30: =RESUMO!J25 -> 0 | N30: =RESUMO!O25 -> 0 | O30: =RESUMO!R25 -> 0 | P30: =RESUMO!K25 -> 0 | Q30: =RESUMO!P25 -> 0 | R30: =1-O30 -> 1 | T30: m | U30: 148.7 | V30: 633 | W30: =ROUND(V30*U30,2) -> 94127.1
B31: B.2.3 | C31: Valeta de proteção de cortes com revestimento de concreto - VPC 04 - areia e brita comerciais | E31: m | F31: 0 | G31: 0 | H31: =F31*G31 -> 0 | I31: =RESUMO!H26 -> 0 | J31: =RESUMO!M26 -> 0 | K31: =RESUMO!I26 -> 0 | L31: =RESUMO!N26 -> 0 | M31: =RESUMO!J26 -> 0 | N31: =RESUMO!O26 -> 0 | O31: =RESUMO!R26 -> 0 | P31: =RESUMO!K26 -> 0 | Q31: =RESUMO!P26 -> 0 | R31: =1-O31 -> 1 | T31: m | U31: 157.87 | V31: 142 | W31: =ROUND(V31*U31,2) -> 22417.54
B32: B.2.4 | C32: Caixa coletora A6 - CCS 200-60A | E32: und. | F32: 0 | G32: 0 | H32: =F32*G32 -> 0 | I32: =RESUMO!H27 -> 0 | J32: =RESUMO!M27 -> 0 | K32: =RESUMO!I27 -> 0 | L32: =RESUMO!N27 -> 0 | M32: =RESUMO!J27 -> 0 | N32: =RESUMO!O27 -> 0 | O32: =RESUMO!R27 -> 0 | P32: =RESUMO!K27 -> 0 | Q32: =RESUMO!P27 -> 0 | R32: =1-O32 -> 1 | T32: und. | U32: 5875.66 | V32: 4 | W32: =ROUND(V32*U32,2) -> 23502.64
B33: B.2.5 | C33: Descida d'água de cortes em degraus - DCD 02 - areia e brita comerciais | E33: m | F33: 0 | G33: 0 | H33: =F33*G33 -> 0 | I33: =RESUMO!H28 -> 0 | J33: =RESUMO!M28 -> 0 | K33: =RESUMO!I28 -> 0 | L33: =RESUMO!N28 -> 0 | M33: =RESUMO!J28 -> 0 | N33: =RESUMO!O28 -> 0 | O33: =RESUMO!R28 -> 0 | P33: =RESUMO!K28 -> 0 | Q33: =RESUMO!P28 -> 0 | R33: =1-O33 -> 1 | T33: m | U33: 963.89 | V33: 151 | W33: =ROUND(V33*U33,2) -> 145547.39
B34: B.2.6 | C34: Descida d'água de cortes em degraus - DCD 100-50 - areia e brita comerciais | E34: m | F34: 1034 | G34: 292.6 | H34: =F34*G34 -> 302548.4 | I34: =RESUMO!H29 -> 0 | J34: =RESUMO!M29 -> 0 | K34: =RESUMO!I29 -> 112.54 | L34: =RESUMO!N29 -> 116366.36 | M34: =RESUMO!J29 -> 112.54 | N34: =RESUMO!O29 -> 116366.36 | O34: =RESUMO!R29 -> 0.38462064 | P34: =RESUMO!K29 -> 180.06 | Q34: =RESUMO!P29 -> 186182.04 | R34: =1-O34 -> 0.61537936
B35: B.2.7 | C35: Valeta de proteção de cortes com revestimento de concreto - VPCC 120-30 - escavação mecânica - areia e brita comerciais | E35: m | F35: 141.79 | G35: 1111 | H35: =F35*G35 -> 157528.69 | I35: =RESUMO!H30 -> 0 | J35: =RESUMO!M30 -> 0 | K35: =RESUMO!I30 -> 1513.65 | L35: =RESUMO!N30 -> 214620.43 | M35: =RESUMO!J30 -> 1513.65 | N35: =RESUMO!O30 -> 214620.43 | O35: =RESUMO!R30 -> 1.3624212 | P35: =RESUMO!K30 -> -402.65 | Q35: =RESUMO!P30 -> -57091.743 | R35: =1-O35 -> -0.36242124
B36: B.2.8 | C36: Caixa coletora de sarjeta - CCS 250-120 A - com grelha de concreto - areia e brita comerciais | E36: und. | F36: 7471.91 | G36: 11 | H36: =F36*G36 -> 82191.01 | I36: =RESUMO!H31 -> 0 | J36: =RESUMO!M31 -> 0 | K36: =RESUMO!I31 -> 4 | L36: =RESUMO!N31 -> 29887.64 | M36: =RESUMO!J31 -> 4 | N36: =RESUMO!O31 -> 29887.64 | O36: =RESUMO!R31 -> 0.36363636 | P36: =RESUMO!K31 -> 7 | Q36: =RESUMO!P31 -> 52303.37 | R36: =1-O36 -> 0.63636364
B37: B.2.9 | C37: Sarjeta triangular de concreto - STC 88-20 - escavação mecânica - areia e brita comerciais | E37: m | F37: 58 | G37: 132 | H37: =F37*G37 -> 7656 | I37: =RESUMO!H32 -> 0 | J37: =RESUMO!M32 -> 0 | K37: =RESUMO!I32 -> 193.37 | L37: =RESUMO!N32 -> 11215.46 | M37: =RESUMO!J32 -> 193.37 | N37: =RESUMO!O32 -> 11215.46 | O37: =RESUMO!R32 -> 1.4649242 | P37: =RESUMO!K32 -> -61.37 | Q37: =RESUMO!P32 -> -3559.46 | R37: =1-O37 -> -0.46492424
B38: B.3 | C38: Revestimento Vegetal | H38: =SUBTOTAL(9,H39:H40) -> 399000 | J38: =SUBTOTAL(9,J39:J40) -> 233722.92 | L38: =SUBTOTAL(9,L39:L40) -> 621222.57 | N38: =SUBTOTAL(9,N39:N40) -> 854945.49 | Q38: =SUBTOTAL(9,Q39:Q40) -> -455945.49 | W38: =SUBTOTAL(9,W39) -> 404800
B39: B.3.1 | C39: Proteção Vegetal (Hidrossemeadura + Biomanta) | E39: m² | F39: 25.3 | G39: 15000 | H39: =F39*G39 -> 379500 | I39: =RESUMO!H34 -> 9238.06 | J39: =RESUMO!M34 -> 233722.92 | K39: =RESUMO!I34 -> 22721.098 | L39: =RESUMO!N34 -> 574843.77 | M39: =RESUMO!J34 -> 31959.158 | N39: =RESUMO!O34 -> 808566.69 | O39: =RESUMO!R34 -> 2.1306105 | P39: =RESUMO!K34 -> -16959.158 | Q39: =RESUMO!P34 -> -429066.69 | R39: =1-O39 -> -1.1306105 | T39: m² | U39: 25.3 | V39: 16000 | W39: =ROUND(V39*U39,2) -> 404800
B40: B.3.2 | C40: Cerca com 4 fios de arame farpado e mourão de concreto de seção quadrada de 11 cm a cada 2,5 m e esticador de 15 cm a cada 50 m - areia e brita comerciais | E40: m | F40: 65 | G40: 300 | H40: =F40*G40 -> 19500 | I40: =RESUMO!H35 -> 0 | J40: =RESUMO!M35 -> 0 | K40: =RESUMO!I35 -> 713.52 | L40: =RESUMO!N35 -> 46378.8 | M40: =RESUMO!J35 -> 713.52 | N40: =RESUMO!O35 -> 46378.8 | O40: =RESUMO!R35 -> 2.3784 | P40: =RESUMO!K35 -> -413.52 | Q40: =RESUMO!P35 -> -26878.8 | R40: =1-O40 -> -1.3784 | T40: m² | U40: 25.3 | V40: 16000 | W40: =ROUND(V40*U40,2) -> 404800
B41: C. | C41: Implantação de Desvio 1 - Km 303+450 - Leste | H41: =SUBTOTAL(9,H42:H67) -> 807697.37 | J41: =SUBTOTAL(9,J42:J67) -> 776624.58 | L41: =SUBTOTAL(9,L42:L67) -> 26511.6 | N41: =SUBTOTAL(9,N42:N67) -> 803136.18 | Q41: =SUBTOTAL(9,Q42:Q67) -> 4561.1893 | W41: =SUBTOTAL(9,W42:W61) -> 673298.87
...

Sheet RESUMO
B1: STATUS | C1: ="CONTRATO: "&CAPA!B4 -> CONTRATO: 381/188/2025 | G1: =CAPA!B5 -> RECOMPOSIÇÃO DE TALUDES - SINISTRO 297+500 - OESTE | N1: R$ MEDIÇÃO ATUAL (PI) | P1: R$ REAJUSTE (BDI - 18,20%) | R1: R$ MEDIÇÃO (PI+BDI)
N2: =SUBTOTAL(9,N8:N100) -> 1990219.7 | P2: =N2*(18.2/100) -> 362219.98 | R2: =SUM(L2:Q2) -> 2352439.6
B4: LINK | C4: =UPPER(IF(PQ!B10="","",PQ!B10)) -> ITEM | D4: =UPPER(IF(PQ!C10="","",PQ!C10)) -> DESCRIÇÃO | E4: =UPPER(IF(PQ!E11="","",PQ!E11)) -> UNID. | F4: =UPPER(IF(PQ!F11="","",PQ!F11)) -> P. UNITÁRIO (R$ / UNID.) | G4: QUANTIDADES | M4: FINANCEIRO | R4: AVANÇO % | S4: DESVIO
G5: PROJETO | H5: ACUMULADO ANTERIOR | I5: MEDIÇÃO ATUAL | J5: ACUMULADO | K5: SALDO | L5: NÃO MEDIDO | M5: ACUMULADO ANTERIOR | N5: MEDIÇÃO ATUAL | O5: ACUMULADO | P5: SALDO | Q5: NÃO MEDIDO
M7: =SUM(M8,M12,M36,M63,M88,M90) -> 3745492.2 | N7: =SUM(N8,N12,N36,N63,N88,N90) -> 1990219.7 | O7: =SUM(O8,O12,O36,O63,O88,O90) -> 5735711.9 | P7: =SUM(P8,P12,P36,P63,P88,P90) -> 94956.86 | Q7: =SUM(Q8,Q12,Q36,Q63,Q88,Q90) -> 217212.11
C8: =IF(PQ!B13="","",PQ!B13) -> A. | D8: =IF(PQ!C13="","",PQ!C13) -> Custos Indiretos | E8: =IF(PQ!E13="","",PQ!E13) | F8: =IF(PQ!F13="","",PQ!F13) | G8: =IF(PQ!G13="","",PQ!G13) | M8: =SUBTOTAL(9,M9:M11) -> 550507.66 | N8: =SUBTOTAL(9,N9:N11) -> 0 | O8: =SUBTOTAL(9,O9:O11) -> 550507.66 | P8: =SUBTOTAL(9,P9:P11) -> 0 | Q8: =SUBTOTAL(9,Q9:Q11) -> 0
B9: =HYPERLINK("#"&"'"&C9&"'"&"!A1","LINK") -> LINK | C9: =IF(PQ!B14="","",PQ!B14) -> A.1 | D9: =IF(PQ!C14="","",PQ!C14) -> Mobilização e desmobilização | E9: =IF(PQ!E14="","",PQ!E14) -> vb. | F9: =IF(PQ!F14="","",PQ!F14) -> 22570.81 | G9: =IF(PQ!G14="","",PQ!G14) -> 1 | H9: {=INDIRECT($C9&"!E6")} -> 1 | I9: {=INDIRECT($C9&"!E9")} -> 0 | J9: {=INDIRECT($C9&"!E5")} -> 1 | K9: {=INDIRECT($C9&"!E7")} -> 0 | L9: {=INDIRECT($C9&"!E8")} -> 0 | M9: {=INDIRECT($C9&"!G6")} -> 22570.81 | N9: {=INDIRECT($C9&"!G9")} -> 0 | O9: {=INDIRECT($C9&"!G5")} -> 22570.81 | P9: {=INDIRECT($C9&"!G7")} -> 0 | Q9: {=INDIRECT($C9&"!G8")} -> 0 | R9: =IF(ISERROR(J9/G9),0,J9/G9) -> 1 | S9: =IF(R9>1,R9-1,0) -> 0
B10: =HYPERLINK("#"&"'"&C10&"'"&"!A1","LINK") -> LINK | C10: =IF(PQ!B15="","",PQ!B15) -> A.2 | D10: =IF(PQ!C15="","",PQ!C15) -> Sinalização e desvio de tráfego | E10: =IF(PQ!E15="","",PQ!E15) -> vb. | F10: =IF(PQ!F15="","",PQ!F15) -> 45141.63 | G10: =IF(PQ!G15="","",PQ!G15) -> 1 | H10: {=INDIRECT($C10&"!E6")} -> 1 | I10: {=INDIRECT($C10&"!E9")} -> 0 | J10: {=INDIRECT($C10&"!E5")} -> 1 | K10: {=INDIRECT($C10&"!E7")} -> 0 | L10: {=INDIRECT($C10&"!E8")} -> 0 | M10: {=INDIRECT($C10&"!G6")} -> 45141.63 | N10: {=INDIRECT($C10&"!G9")} -> 0 | O10: {=INDIRECT($C10&"!G5")} -> 45141.63 | P10: {=INDIRECT($C10&"!G7")} -> 0 | Q10: {=INDIRECT($C10&"!G8")} -> 0 | R10: =IF(ISERROR(J10/G10),0,J10/G10) -> 1 | S10: =IF(R10>1,R10-1,0) -> 0
B11: =HYPERLINK("#"&"'"&C11&"'"&"!A1","LINK") -> LINK | C11: =IF(PQ!B16="","",PQ!B16) -> A.3 | D11: =IF(PQ!C16="","",PQ!C16) -> Administração local | E11: =IF(PQ!E16="","",PQ!E16) -> vb. | F11: =IF(PQ!F16="","",PQ!F16) -> 482795.22 | G11: =IF(PQ!G16="","",PQ!G16) -> 1 | H11: {=INDIRECT($C11&"!E6")} -> 1 | I11: {=INDIRECT($C11&"!E9")} -> 0 | J11: {=INDIRECT($C11&"!E5")} -> 1 | K11: {=INDIRECT($C11&"!E7")} -> 0 | L11: {=INDIRECT($C11&"!E8")} -> 0 | M11: {=INDIRECT($C11&"!G6")} -> 482795.22 | N11: {=INDIRECT($C11&"!G9")} -> 0 | O11: {=INDIRECT($C11&"!G5")} -> 482795.22 | P11: {=INDIRECT($C11&"!G7")} -> 0 | Q11: {=INDIRECT($C11&"!G8")} -> 0 | R11: =IF(ISERROR(J11/G11),0,J11/G11) -> 1 | S11: =IF(R11>1,R11-1,0) -> 0
C12: =IF(PQ!B17="","",PQ!B17) -> B. | D12: =IF(PQ!C17="","",PQ!C17) -> Estabilização de Talude | E12: =IF(PQ!E17="","",PQ!E17) | F12: =IF(PQ!F17="","",PQ!F17) | G12: =IF(PQ!G17="","",PQ!G17) | M12: =SUBTOTAL(9,M13:M35) -> 1998206.6 | N12: =SUBTOTAL(9,N13:N35) -> 1870605.8 | O12: =SUBTOTAL(9,O13:O35) -> 3868812.4 | P12: =SUBTOTAL(9,P13:P35) -> -193535.02 | Q12: =SUBTOTAL(9,Q13:Q35) -> 171481.92
C13: =IF(PQ!B18="","",PQ!B18) -> B.1 | D13: =IF(PQ!C18="","",PQ!C18) -> Terraplenagem | E13: =IF(PQ!E18="","",PQ!E18) | F13: =IF(PQ!F18="","",PQ!F18) | G13: =IF(PQ!G18="","",PQ!G18) | M13: =SUBTOTAL(9,M14:M22) -> 1764483.7 | N13: =SUBTOTAL(9,N14:N22) -> 877293.31 | O13: =SUBTOTAL(9,O14:O22) -> 2641777 | P13: =SUBTOTAL(9,P14:P22) -> 84576.263 | Q13: =SUBTOTAL(9,Q14:Q22) -> 0
B14: =HYPERLINK("#"&"'"&C14&"'"&"!A1","LINK") -> LINK | C14: =IF(PQ!B19="","",PQ!B19) -> B.1.1 | D14: =IF(PQ!C19="","",PQ!C19) -> Escavação, carga e transporte de material de 1ª categoria - DMT de 800 a 1.000 m - caminho de serviço pavimentado - com escavadeira e caminhão basculante de 14 m³ | E14: =IF(PQ!E19="","",PQ!E19) -> m³ | F14: =IF(PQ!F19="","",PQ!F19) -> 0 | G14: =IF(PQ!G19="","",PQ!G19) -> 0 | H14: {=INDIRECT($C14&"!E6")} -> 0 | I14: {=INDIRECT($C14&"!E9")} -> 0 | J14: {=INDIRECT($C14&"!E5")} -> 0 | K14: {=INDIRECT($C14&"!E7")} -> 0 | L14: {=INDIRECT($C14&"!E8")} -> 0 | M14: {=INDIRECT($C14&"!G6")} -> 0 | N14: {=INDIRECT($C14&"!G9")} -> 0 | O14: {=INDIRECT($C14&"!G5")} -> 0 | P14: {=INDIRECT($C14&"!G7")} -> 0 | Q14: {=INDIRECT($C14&"!G8")} -> 0 | R14: =IF(ISERROR(J14/G14),0,J14/G14) -> 0 | S14: =IF(R14>1,R14-1,0) -> 0
B15: =HYPERLINK("#"&"'"&C15&"'"&"!A1","LINK") -> LINK | C15: =IF(PQ!B20="","",PQ!B20) -> B.1.2 | D15: =IF(PQ!C20="","",PQ!C20) -> Escavação e carga de material de 1ª categoria - DMT acima de 3.000 m | E15: =IF(PQ!E20="","",PQ!E20) -> m³ | F15: =IF(PQ!F20="","",PQ!F20) -> 15.86326 | G15: =IF(PQ!G20="","",PQ!G20) -> 72616.71 | H15: {=INDIRECT($C15&"!E6")} -> 62616.71 | I15: {=INDIRECT($C15&"!E9")} -> 6145.816 | J15: {=INDIRECT($C15&"!E5")} -> 68762.526 | K15: {=INDIRECT($C15&"!E7")} -> 3854.184 | L15: {=INDIRECT($C15&"!E8")} -> 0 | M15: {=INDIRECT($C15&"!G6")} -> 993305.14 | N15: {=INDIRECT($C15&"!G9")} -> 97492.676 | O15: {=INDIRECT($C15&"!G5")} -> 1090797.8 | P15: {=INDIRECT($C15&"!G7")} -> 61139.922 | Q15: {=INDIRECT($C15&"!G8")} -> 0 | R15: =IF(ISERROR(J15/G15),0,J15/G15) -> 0.94692428 | S15: =IF(R15>1,R15-1,0) -> 0
B16: =HYPERLINK("#"&"'"&C16&"'"&"!A1","LINK") -> LINK | C16: =IF(PQ!B21="","",PQ!B21) -> B.1.3 | D16: =IF(PQ!C21="","",PQ!C21) -> Transporte com caminhão basculante de 10 m³ - rodovia pavimentada (DMT 5 Km) | E16: =IF(PQ!E21="","",PQ!E21) -> T x Km | F16: =IF(PQ!F21="","",PQ!F21) -> 1.0278799 | G16: =IF(PQ!G21="","",PQ!G21) -> 543194.94 | H16: {=INDIRECT($C16&"!E6")} -> 483457.86 | I16: {=INDIRECT($C16&"!E9")} -> 47451.28 | J16: {=INDIRECT($C16&"!E5")} -> 530909.14 | K16: {=INDIRECT($C16&"!E7")} -> 12285.803 | L16: {=INDIRECT($C16&"!E8")} -> 0 | M16: {=INDIRECT($C16&"!G6")} -> 496936.61 | N16: {=INDIRECT($C16&"!G9")} -> 48774.217 | O16: {=INDIRECT($C16&"!G5")} -> 545710.83 | P16: {=INDIRECT($C16&"!G7")} -> 12628.33 | Q16: {=INDIRECT($C16&"!G8")} -> 0 | R16: =IF(ISERROR(J16/G16),0,J16/G16) -> 0.97738233 | S16: =IF(R16>1,R16-1,0) -> 0
B17: =HYPERLINK("#"&"'"&C17&"'"&"!A1","LINK") -> LINK | C17: =IF(PQ!B22="","",PQ!B22) -> B.1.4 | D17: =IF(PQ!C22="","",PQ!C22) -> Regularização de bota-fora com espalhamento e execução de hidrossemeadura | E17: =IF(PQ!E22="","",PQ!E22) -> m³ | F17: =IF(PQ!F22="","",PQ!F22) -> 0 | G17: =IF(PQ!G22="","",PQ!G22) -> 0 | H17: {=INDIRECT($C17&"!E6")} -> 0 | I17: {=INDIRECT($C17&"!E9")} -> 0 | J17: {=INDIRECT($C17&"!E5")} -> 0 | K17: {=INDIRECT($C17&"!E7")} -> 0 | L17: {=INDIRECT($C17&"!E8")} -> 0 | M17: {=INDIRECT($C17&"!G6")} -> 0 | N17: {=INDIRECT($C17&"!G9")} -> 0 | O17: {=INDIRECT($C17&"!G5")} -> 0 | P17: {=INDIRECT($C17&"!G7")} -> 0 | Q17: {=INDIRECT($C17&"!G8")} -> 0 | R17: =IF(ISERROR(J17/G17),0,J17/G17) -> 0 | S17: =IF(R17>1,R17-1,0) -> 0
B18: =HYPERLINK("#"&"'"&C18&"'"&"!A1","LINK") -> LINK | C18: =IF(PQ!B23="","",PQ!B23) -> B.1.5 | D18: =IF(PQ!C23="","",PQ!C23) -> Royaltie de bota-fora | E18: =IF(PQ!E23="","",PQ!E23) -> m³ | F18: =IF(PQ!F23="","",PQ!F23) -> 0 | G18: =IF(PQ!G23="","",PQ!G23) -> 0 | H18: {=INDIRECT($C18&"!E6")} -> 0 | I18: {=INDIRECT($C18&"!E9")} -> 0 | J18: {=INDIRECT($C18&"!E5")} -> 0 | K18: {=INDIRECT($C18&"!E7")} -> 0 | L18: {=INDIRECT($C18&"!E8")} -> 0 | M18: {=INDIRECT($C18&"!G6")} -> 0 | N18: {=INDIRECT($C18&"!G9")} -> 0 | O18: {=INDIRECT($C18&"!G5")} -> 0 | P18: {=INDIRECT($C18&"!G7")} -> 0 | Q18: {=INDIRECT($C18&"!G8")} -> 0 | R18: =IF(ISERROR(J18/G18),0,J18/G18) -> 0 | S18: =IF(R18>1,R18-1,0) -> 0
B19: =HYPERLINK("#"&"'"&C19&"'"&"!A1","LINK") -> LINK | C19: =IF(PQ!B24="","",PQ!B24) -> B.1.6 | D19: =IF(PQ!C24="","",PQ!C24) -> Desmatamento, destocamento, limpeza de área e estocagem do material de limpeza com árvores de diâmetro até 0,15 m | E19: =IF(PQ!E24="","",PQ!E24) -> m² | F19: =IF(PQ!F24="","",PQ!F24) -> 0.85999993 | G19: =IF(PQ!G24="","",PQ!G24) -> 23377.56 | H19: {=INDIRECT($C19&"!E6")} -> 0 | I19: {=INDIRECT($C19&"!E9")} -> 21252.33 | J19: {=INDIRECT($C19&"!E5")} -> 21252.33 | K19: {=INDIRECT($C19&"!E7")} -> 2125.23 | L19: {=INDIRECT($C19&"!E8")} -> 0 | M19: {=INDIRECT($C19&"!G6")} -> 0 | N19: {=INDIRECT($C19&"!G9")} -> 18277.002 | O19: {=INDIRECT($C19&"!G5")} -> 18277.002 | P19: {=INDIRECT($C19&"!G7")} -> 1827.6977 | Q19: {=INDIRECT($C19&"!G8")} -> 0 | R19: =IF(ISERROR(J19/G19),0,J19/G19) -> 0.90909103 | S19: =IF(R19>1,R19-1,0) -> 0
B20: =HYPERLINK("#"&"'"&C20&"'"&"!A1","LINK") -> LINK | C20: =IF(PQ!B25="","",PQ!B25) -> B.1.7 | D20: =IF(PQ!C25="","",PQ!C25) -> Escavação, carga e transporte de material de 1ª categoria - DMT de 1.400 a 1.600 m - caminho de serviço pavimentado - com escavadeira e caminhão basculante de 14 m³ | E20: =IF(PQ!E25="","",PQ!E25) -> m³ | F20: =IF(PQ!F25="","",PQ!F25) -> 12.629999 | G20: =IF(PQ!G25="","",PQ!G25) -> 55083.7 | H20: {=INDIRECT($C20&"!E6")} -> 0 | I20: {=INDIRECT($C20&"!E9")} -> 55083.697 | J20: {=INDIRECT($C20&"!E5")} -> 55083.697 | K20: {=INDIRECT($C20&"!E7")} -> 0.003 | L20: {=INDIRECT($C20&"!E8")} -> 0 | M20: {=INDIRECT($C20&"!G6")} -> 0 | N20: {=INDIRECT($C20&"!G9")} -> 695707.05 | O20: {=INDIRECT($C20&"!G5")} -> 695707.05 | P20: {=INDIRECT($C20&"!G7")} -> 0.037889998 | Q20: {=INDIRECT($C20&"!G8")} -> 0 | R20: =IF(ISERROR(J20/G20),0,J20/G20) -> 0.99999995 | S20: =IF(R20>1,R20-1,0) -> 0
B21: =HYPERLINK("#"&"'"&C21&"'"&"!A1","LINK") -> LINK | C21: =IF(PQ!B26="","",PQ!B26) -> B.1.8 | D21: =IF(PQ!C26="","",PQ!C26) -> Escavação e carga de material de 2ª categoria - DMT acima de 3.000 m | E21: =IF(PQ!E26="","",PQ!E26) -> m³ | F21: =IF(PQ!F26="","",PQ!F26) -> 19.519859 | G21: =IF(PQ!G26="","",PQ!G26) -> 139.48 | H21: {=INDIRECT($C21&"!E6")} -> 0 | I21: {=INDIRECT($C21&"!E9")} -> 139.479 | J21: {=INDIRECT($C21&"!E5")} -> 139.479 | K21: {=INDIRECT($C21&"!E7")} -> 0.001 | L21: {=INDIRECT($C21&"!E8")} -> 0 | M21: {=INDIRECT($C21&"!G6")} -> 0 | N21: {=INDIRECT($C21&"!G9")} -> 2722.6105 | O21: {=INDIRECT($C21&"!G5")} -> 2722.6105 | P21: {=INDIRECT($C21&"!G7")} -> 0.019519859 | Q21: {=INDIRECT($C21&"!G8")} -> 0 | R21: =IF(ISERROR(J21/G21),0,J21/G21) -> 0.99999283 | S21: =IF(R21>1,R21-1,0) -> 0
B22: =HYPERLINK("#"&"'"&C22&"'"&"!A1","LINK") -> LINK | C22: =IF(PQ!B27="","",PQ!B27) -> B.1.9 | D22: =IF(PQ!C27="","",PQ!C27) -> Regularização de bota-fora | E22: =IF(PQ!E27="","",PQ!E27) -> m³ | F22: =IF(PQ!F27="","",PQ!F27) -> 2.33 | G22: =IF(PQ!G27="","",PQ!G27) -> 127700.41 | H22: {=INDIRECT($C22&"!E6")} -> 117700.41 | I22: {=INDIRECT($C22&"!E9")} -> 6145.816 | J22: {=INDIRECT($C22&"!E5")} -> 123846.22 | K22: {=INDIRECT($C22&"!E7")} -> 3854.187 | L22: {=INDIRECT($C22&"!E8")} -> 0 | M22: {=INDIRECT($C22&"!G6")} -> 274241.94 | N22: {=INDIRECT($C22&"!G9")} -> 14319.751 | O22: {=INDIRECT($C22&"!G5")} -> 288561.69 | P22: {=INDIRECT($C22&"!G7")} -> 8980.2556 | Q22: {=INDIRECT($C22&"!G8")} -> 0 | R22: =IF(ISERROR(J22/G22),0,J22/G22) -> 0.96981852 | S22: =IF(R22>1,R22-1,0) -> 0
C23: =IF(PQ!B28="","",PQ!B28) -> B.2 | D23: =IF(PQ!C28="","",PQ!C28) -> Drenagem e OACs | E23: =IF(PQ!E28="","",PQ!E28) | F23: =IF(PQ!F28="","",PQ!F28) | G23: =IF(PQ!G28="","",PQ!G28) | M23: =SUBTOTAL(9,M24:M32) -> 0 | N23: =SUBTOTAL(9,N24:N32) -> 372089.89 | O23: =SUBTOTAL(9,O24:O32) -> 372089.89 | P23: =SUBTOTAL(9,P24:P32) -> 177834.21 | Q23: =SUBTOTAL(9,Q24:Q32) -> 0
B24: =HYPERLINK("#"&"'"&C24&"'"&"!A1","LINK") -> LINK | C24: =IF(PQ!B29="","",PQ!B29) -> B.2.1 | D24: =IF(PQ!C29="","",PQ!C29) -> Demolição de dispositivos de drenagem | E24: =IF(PQ!E29="","",PQ!E29) -> m³ | F24: =IF(PQ!F29="","",PQ!F29) -> 0 | G24: =IF(PQ!G29="","",PQ!G29) -> 0 | H24: {=INDIRECT($C24&"!E6")} -> 0 | I24: {=INDIRECT($C24&"!E9")} -> 0 | J24: {=INDIRECT($C24&"!E5")} -> 0 | K24: {=INDIRECT($C24&"!E7")} -> 0 | L24: {=INDIRECT($C24&"!E8")} -> 0 | M24: {=INDIRECT($C24&"!G6")} -> 0 | N24: {=INDIRECT($C24&"!G9")} -> 0 | O24: {=INDIRECT($C24&"!G5")} -> 0 | P24: {=INDIRECT($C24&"!G7")} -> 0 | Q24: {=INDIRECT($C24&"!G8")} -> 0 | R24: =IF(ISERROR(J24/G24),0,J24/G24) -> 0 | S24: =IF(R24>1,R24-1,0) -> 0
B25: =HYPERLINK("#"&"'"&C25&"'"&"!A1","LINK") -> LINK | C25: =IF(PQ!B30="","",PQ!B30) -> B.2.2 | D25: =IF(PQ!C30="","",PQ!C30) -> Sarjeta triangular de concreto - STC 150-30 - escavação mecânica - areia e brita comerciais | E25: =IF(PQ!E30="","",PQ!E30) -> m | F25: =IF(PQ!F30="","",PQ!F30) -> 0 | G25: =IF(PQ!G30="","",PQ!G30) -> 0 | H25: {=INDIRECT($C25&"!E6")} -> 0 | I25: {=INDIRECT($C25&"!E9")} -> 0 | J25: {=INDIRECT($C25&"!E5")} -> 0 | K25: {=INDIRECT($C25&"!E7")} -> 0 | L25: {=INDIRECT($C25&"!E8")} -> 0 | M25: {=INDIRECT($C25&"!G6")} -> 0 | N25: {=INDIRECT($C25&"!G9")} -> 0 | O25: {=INDIRECT($C25&"!G5")} -> 0 | P25: {=INDIRECT($C25&"!G7")} -> 0 | Q25: {=INDIRECT($C25&"!G8")} -> 0 | R25: =IF(ISERROR(J25/G25),0,J25/G25) -> 0 | S25: =IF(R25>1,R25-1,0) -> 0
B26: =HYPERLINK("#"&"'"&C26&"'"&"!A1","LINK") -> LINK | C26: =IF(PQ!B31="","",PQ!B31) -> B.2.3 | D26: =IF(PQ!C31="","",PQ!C31) -> Valeta de proteção de cortes com revestimento de concreto - VPC 04 - areia e brita comerciais | E26: =IF(PQ!E31="","",PQ!E31) -> m | F26: =IF(PQ!F31="","",PQ!F31) -> 0 | G26: =IF(PQ!G31="","",PQ!G31) -> 0 | H26: {=INDIRECT($C26&"!E6")} -> 0 | I26: {=INDIRECT($C26&"!E9")} -> 0 | J26: {=INDIRECT($C26&"!E5")} -> 0 | K26: {=INDIRECT($C26&"!E7")} -> 0 | L26: {=INDIRECT($C26&"!E8")} -> 0 | M26: {=INDIRECT($C26&"!G6")} -> 0 | N26: {=INDIRECT($C26&"!G9")} -> 0 | O26: {=INDIRECT($C26&"!G5")} -> 0 | P26: {=INDIRECT($C26&"!G7")} -> 0 | Q26: {=INDIRECT($C26&"!G8")} -> 0 | R26: =IF(ISERROR(J26/G26),0,J26/G26) -> 0 | S26: =IF(R26>1,R26-1,0) -> 0
B27: =HYPERLINK("#"&"'"&C27&"'"&"!A1","LINK") -> LINK | C27: =IF(PQ!B32="","",PQ!B32) -> B.2.4 | D27: =IF(PQ!C32="","",PQ!C32) -> Caixa coletora A6 - CCS 200-60A | E27: =IF(PQ!E32="","",PQ!E32) -> und. | F27: =IF(PQ!F32="","",PQ!F32) -> 0 | G27: =IF(PQ!G32="","",PQ!G32) -> 0 | H27: {=INDIRECT($C27&"!E6")} -> 0 | I27: {=INDIRECT($C27&"!E9")} -> 0 | J27: {=INDIRECT($C27&"!E5")} -> 0 | K27: {=INDIRECT($C27&"!E7")} -> 0 | L27: {=INDIRECT($C27&"!E8")} -> 0 | M27: {=INDIRECT($C27&"!G6")} -> 0 | N27: {=INDIRECT($C27&"!G9")} -> 0 | O27: {=INDIRECT($C27&"!G5")} -> 0 | P27: {=INDIRECT($C27&"!G7")} -> 0 | Q27: {=INDIRECT($C27&"!G8")} -> 0 | R27: =IF(ISERROR(J27/G27),0,J27/G27) -> 0 | S27: =IF(R27>1,R27-1,0) -> 0
B28: =HYPERLINK("#"&"'"&C28&"'"&"!A1","LINK") -> LINK | C28: =IF(PQ!B33="","",PQ!B33) -> B.2.5 | D28: =IF(PQ!C33="","",PQ!C33) -> Descida d'água de cortes em degraus - DCD 02 - areia e brita comerciais | E28: =IF(PQ!E33="","",PQ!E33) -> m | F28: =IF(PQ!F33="","",PQ!F33) -> 0 | G28: =IF(PQ!G33="","",PQ!G33) -> 0 | H28: {=INDIRECT($C28&"!E6")} -> 0 | I28: {=INDIRECT($C28&"!E9")} -> 0 | J28: {=INDIRECT($C28&"!E5")} -> 0 | K28: {=INDIRECT($C28&"!E7")} -> 0 | L28: {=INDIRECT($C28&"!E8")} -> 0 | M28: {=INDIRECT($C28&"!G6")} -> 0 | N28: {=INDIRECT($C28&"!G9")} -> 0 | O28: {=INDIRECT($C28&"!G5")} -> 0 | P28: {=INDIRECT($C28&"!G7")} -> 0 | Q28: {=INDIRECT($C28&"!G8")} -> 0 | R28: =IF(ISERROR(J28/G28),0,J28/G28) -> 0 | S28: =IF(R28>1,R28-1,0) -> 0
B29: =HYPERLINK("#"&"'"&C29&"'"&"!A1","LINK") -> LINK | C29: =IF(PQ!B34="","",PQ!B34) -> B.2.6 | D29: =IF(PQ!C34="","",PQ!C34) -> Descida d'água de cortes em degraus - DCD 100-50 - areia e brita comerciais | E29: =IF(PQ!E34="","",PQ!E34) -> m | F29: =IF(PQ!F34="","",PQ!F34) -> 1034 | G29: =IF(PQ!G34="","",PQ!G34) -> 292.6 | H29: {=INDIRECT($C29&"!E6")} -> 0 | I29: {=INDIRECT($C29&"!E9")} -> 112.54 | J29: {=INDIRECT($C29&"!E5")} -> 112.54 | K29: {=INDIRECT($C29&"!E7")} -> 180.06 | L29: {=INDIRECT($C29&"!E8")} -> 0 | M29: {=INDIRECT($C29&"!G6")} -> 0 | N29: {=INDIRECT($C29&"!G9")} -> 116366.36 | O29: {=INDIRECT($C29&"!G5")} -> 116366.36 | P29: {=INDIRECT($C29&"!G7")} -> 186182.04 | Q29: {=INDIRECT($C29&"!G8")} -> 0 | R29: =IF(ISERROR(J29/G29),0,J29/G29) -> 0.38462064 | S29: =IF(R29>1,R29-1,0) -> 0
B30: =HYPERLINK("#"&"'"&C30&"'"&"!A1","LINK") -> LINK | C30: =IF(PQ!B35="","",PQ!B35) -> B.2.7 | D30: =IF(PQ!C35="","",PQ!C35) -> Valeta de proteção de cortes com revestimento de concreto - VPCC 120-30 - escavação mecânica - areia e brita comerciais | E30: =IF(PQ!E35="","",PQ!E35) -> m | F30: =IF(PQ!F35="","",PQ!F35) -> 141.79 | G30: =IF(PQ!G35="","",PQ!G35) -> 1111 | H30: {=INDIRECT($C30&"!E6")} -> 0 | I30: {=INDIRECT($C30&"!E9")} -> 1513.65 | J30: {=INDIRECT($C30&"!E5")} -> 1513.65 | K30: {=INDIRECT($C30&"!E7")} -> -402.65 | L30: {=INDIRECT($C30&"!E8")} -> 0 | M30: {=INDIRECT($C30&"!G6")} -> 0 | N30: {=INDIRECT($C30&"!G9")} -> 214620.43 | O30: {=INDIRECT($C30&"!G5")} -> 214620.43 | P30: {=INDIRECT($C30&"!G7")} -> -57091.743 | Q30: {=INDIRECT($C30&"!G8")} -> 0 | R30: =IF(ISERROR(J30/G30),0,J30/G30) -> 1.3624212 | S30: =IF(R30>1,R30-1,0) -> 0.36242124
B31: =HYPERLINK("#"&"'"&C31&"'"&"!A1","LINK") -> LINK | C31: =IF(PQ!B36="","",PQ!B36) -> B.2.8 | D31: =IF(PQ!C36="","",PQ!C36) -> Caixa coletora de sarjeta - CCS 250-120 A - com grelha de concreto - areia e brita comerciais | E31: =IF(PQ!E36="","",PQ!E36) -> und. | F31: =IF(PQ!F36="","",PQ!F36) -> 7471.91 | G31: =IF(PQ!G36="","",PQ!G36) -> 11 | H31: {=INDIRECT($C31&"!E6")} -> 0 | I31: {=INDIRECT($C31&"!E9")} -> 4 | J31: {=INDIRECT($C31&"!E5")} -> 4 | K31: {=INDIRECT($C31&"!E7")} -> 7 | L31: {=INDIRECT($C31&"!E8")} -> 0 | M31: {=INDIRECT($C31&"!G6")} -> 0 | N31: {=INDIRECT($C31&"!G9")} -> 29887.64 | O31: {=INDIRECT($C31&"!G5")} -> 29887.64 | P31: {=INDIRECT($C31&"!G7")} -> 52303.37 | Q31: {=INDIRECT($C31&"!G8")} -> 0 | R31: =IF(ISERROR(J31/G31),0,J31/G31) -> 0.36363636 | S31: =IF(R31>1,R31-1,0) -> 0
B32: =HYPERLINK("#"&"'"&C32&"'"&"!A1","LINK") -> LINK | C32: =IF(PQ!B37="","",PQ!B37) -> B.2.9 | D32: =IF(PQ!C37="","",PQ!C37) -> Sarjeta triangular de concreto - STC 88-20 - escavação mecânica - areia e brita comerciais | E32: =IF(PQ!E37="","",PQ!E37) -> m | F32: =IF(PQ!F37="","",PQ!F37) -> 58 | G32: =IF(PQ!G37="","",PQ!G37) -> 132 | H32: {=INDIRECT($C32&"!E6")} -> 0 | I32: {=INDIRECT($C32&"!E9")} -> 193.37 | J32: {=INDIRECT($C32&"!E5")} -> 193.37 | K32: {=INDIRECT($C32&"!E7")} -> -61.37 | L32: {=INDIRECT($C32&"!E8")} -> 0 | M32: {=INDIRECT($C32&"!G6")} -> 0 | N32: {=INDIRECT($C32&"!G9")} -> 11215.46 | O32: {=INDIRECT($C32&"!G5")} -> 11215.46 | P32: {=INDIRECT($C32&"!G7")} -> -3559.46 | Q32: {=INDIRECT($C32&"!G8")} -> 0 | R32: =IF(ISERROR(J32/G32),0,J32/G32) -> 1.4649242 | S32: =IF(R32>1,R32-1,0) -> 0.46492424
C33: =IF(PQ!B38="","",PQ!B38) -> B.3 | D33: =IF(PQ!C38="","",PQ!C38) -> Revestimento Vegetal | E33: =IF(PQ!E38="","",PQ!E38) | F33: =IF(PQ!F38="","",PQ!F38) | G33: =IF(PQ!G38="","",PQ!G38) | M33: =SUBTOTAL(9,M34:M35) -> 233722.92 | N33: =SUBTOTAL(9,N34:N35) -> 621222.57 | O33: =SUBTOTAL(9,O34:O35) -> 854945.49 | P33: =SUBTOTAL(9,P34:P35) -> -455945.49 | Q33: =SUBTOTAL(9,Q34:Q35) -> 171481.92
B34: =HYPERLINK("#"&"'"&C34&"'"&"!A1","LINK") -> LINK | C34: =IF(PQ!B39="","",PQ!B39) -> B.3.1 | D34: =IF(PQ!C39="","",PQ!C39) -> Proteção Vegetal (Hidrossemeadura + Biomanta) | E34: =IF(PQ!E39="","",PQ!E39) -> m² | F34: =IF(PQ!F39="","",PQ!F39) -> 25.3 | G34: =IF(PQ!G39="","",PQ!G39) -> 15000 | H34: {=INDIRECT($C34&"!E6")} -> 9238.06 | I34: {=INDIRECT($C34&"!E9")} -> 22721.098 | J34: {=INDIRECT($C34&"!E5")} -> 31959.158 | K34: {=INDIRECT($C34&"!E7")} -> -16959.158 | L34: {=INDIRECT($C34&"!E8")} -> 6777.9414 | M34: {=INDIRECT($C34&"!G6")} -> 233722.92 | N34: {=INDIRECT($C34&"!G9")} -> 574843.77 | O34: {=INDIRECT($C34&"!G5")} -> 808566.69 | P34: {=INDIRECT($C34&"!G7")} -> -429066.69 | Q34: {=INDIRECT($C34&"!G8")} -> 171481.92 | R34: =IF(ISERROR(J34/G34),0,J34/G34) -> 2.1306105 | S34: =IF(R34>1,R34-1,0) -> 1.1306105
B35: =HYPERLINK("#"&"'"&C35&"'"&"!A1","LINK") -> LINK | C35: =IF(PQ!B40="","",PQ!B40) -> B.3.2 | D35: =IF(PQ!C40="","",PQ!C40) -> Cerca com 4 fios de arame farpado e mourão de concreto de seção quadrada de 11 cm a cada 2,5 m e esticador de 15 cm a cada 50 m - areia e brita comerciais | E35: =IF(PQ!E40="","",PQ!E40) -> m | F35: =IF(PQ!F40="","",PQ!F40) -> 65 | G35: =IF(PQ!G40="","",PQ!G40) -> 300 | H35: {=INDIRECT($C35&"!E6")} -> 0 | I35: {=INDIRECT($C35&"!E9")} -> 713.52 | J35: {=INDIRECT($C35&"!E5")} -> 713.52 | K35: {=INDIRECT($C35&"!E7")} -> -413.52 | L35: {=INDIRECT($C35&"!E8")} -> 0 | M35: {=INDIRECT($C35&"!G6")} -> 0 | N35: {=INDIRECT($C35&"!G9")} -> 46378.8 | O35: {=INDIRECT($C35&"!G5")} -> 46378.8 | P35: {=INDIRECT($C35&"!G7")} -> -26878.8 | Q35: {=INDIRECT($C35&"!G8")} -> 0 | R35: =IF(ISERROR(J35/G35),0,J35/G35) -> 2.3784 | S35: =IF(R35>1,R35-1,0) -> 1.3784
C36: =IF(PQ!B41="","",PQ!B41) -> C. | D36: =IF(PQ!C41="","",PQ!C41) -> Implantação de Desvio 1 - Km 303+450 - Leste | E36: =IF(PQ!E41="","",PQ!E41) | F36: =IF(PQ!F41="","",PQ!F41) | G36: =IF(PQ!G41="","",PQ!G41) | M36: =SUBTOTAL(9,M37:M62) -> 776624.58 | N36: =SUBTOTAL(9,N37:N62) -> 26511.6 | O36: =SUBTOTAL(9,O37:O62) -> 803136.18 | P36: =SUBTOTAL(9,P37:P62) -> 4561.1893 | Q36: =SUBTOTAL(9,Q37:Q62) -> 0
C37: =IF(PQ!B42="","",PQ!B42) -> C.1 | D37: =IF(PQ!C42="","",PQ!C42) -> Terraplenagem | E37: =IF(PQ!E42="","",PQ!E42) | F37: =IF(PQ!F42="","",PQ!F42) | G37: =IF(PQ!G42="","",PQ!G42) | M37: =SUBTOTAL(9,M38:M42) -> 24752.505 | N37: =SUBTOTAL(9,N38:N42) -> 0 | O37: =SUBTOTAL(9,O38:O42) -> 24752.505 | P37: =SUBTOTAL(9,P38:P42) -> 14813.305 | Q37: =SUBTOTAL(9,Q38:Q42) -> 0
B38: =HYPERLINK("#"&"'"&C38&"'"&"!A1","LINK") -> LINK | C38: =IF(PQ!B43="","",PQ!B43) -> C.1.1 | D38: =IF(PQ!C43="","",PQ!C43) -> Desmatamento, destocamento, limpeza de área e estocagem do material de limpeza com árvores de diâmetro até 0,15 m | E38: =IF(PQ!E43="","",PQ!E43) -> m² | F38: =IF(PQ!F43="","",PQ!F43) -> 0.8599999 | G38: =IF(PQ!G43="","",PQ!G43) -> 7740.78 | H38: {=INDIRECT($C38&"!E6")} -> 7740.779 | I38: {=INDIRECT($C38&"!E9")} -> 0 | J38: {=INDIRECT($C38&"!E5")} -> 7740.779 | K38: {=INDIRECT($C38&"!E7")} -> 0.001 | L38: {=INDIRECT($C38&"!E8")} -> 0 | M38: {=INDIRECT($C38&"!G6")} -> 6657.0691 | N38: {=INDIRECT($C38&"!G9")} -> 0 | O38: {=INDIRECT($C38&"!G5")} -> 6657.0691 | P38: {=INDIRECT($C38&"!G7")} -> 0.0008599999 | Q38: {=INDIRECT($C38&"!G8")} -> 0 | R38: =IF(ISERROR(J38/G38),0,J38/G38) -> 0.99999987 | S38: =IF(R38>1,R38-1,0) -> 0
B39: =HYPERLINK("#"&"'"&C39&"'"&"!A1","LINK") -> LINK | C39: =IF(PQ!B44="","",PQ!B44) -> C.1.2 | D39: =IF(PQ!C44="","",PQ!C44) -> Transporte com caminhão basculante de 14 m³ - rodovia pavimentada | E39: =IF(PQ!E44="","",PQ!E44) -> T x Km | F39: =IF(PQ!F44="","",PQ!F44) -> 1.539998 | G39: =IF(PQ!G44="","",PQ!G44) -> 603.78 | H39: {=INDIRECT($C39&"!E6")} -> 603.78076 | I39: {=INDIRECT($C39&"!E9")} -> 0 | J39: {=INDIRECT($C39&"!E5")} -> 603.78076 | K39: {=INDIRECT($C39&"!E7")} -> -0.000762 | L39: {=INDIRECT($C39&"!E8")} -> 0 | M39: {=INDIRECT($C39&"!G6")} -> 929.82117 | N39: {=INDIRECT($C39&"!G9")} -> 0 | O39: {=INDIRECT($C39&"!G5")} -> 929.82117 | P39: {=INDIRECT($C39&"!G7")} -> -0.0011734785 | Q39: {=INDIRECT($C39&"!G8")} -> 0 | R39: =IF(ISERROR(J39/G39),0,J39/G39) -> 1.0000013 | S39: =IF(R39>1,R39-1,0) -> 1.2620491e-06
B40: =HYPERLINK("#"&"'"&C40&"'"&"!A1","LINK") -> LINK | C40: =IF(PQ!B45="","",PQ!B45) -> C.1.3 | D40: =IF(PQ!C45="","",PQ!C45) -> Escavação, carga e transporte de material de 1ª categoria - DMT de 1.000 a 1.200 m - com escavadeira e caminhão basculante de 14 m³ | E40: =IF(PQ!E45="","",PQ!E45) -> m³ | F40: =IF(PQ!F45="","",PQ!F45) -> 0 | G40: =IF(PQ!G45="","",PQ!G45) -> 0 | H40: {=INDIRECT($C40&"!E6")} -> 6679.445 | I40: {=INDIRECT($C40&"!E9")} -> 0 | J40: {=INDIRECT($C40&"!E5")} -> 6679.445 | K40: {=INDIRECT($C40&"!E7")} -> -6679.445 | L40: {=INDIRECT($C40&"!E8")} -> 0 | M40: {=INDIRECT($C40&"!G6")} -> 0 | N40: {=INDIRECT($C40&"!G9")} -> 0 | O40: {=INDIRECT($C40&"!G5")} -> 0 | P40: {=INDIRECT($C40&"!G7")} -> 0 | Q40: {=INDIRECT($C40&"!G8")} -> 0 | R40: =IF(ISERROR(J40/G40),0,J40/G40) -> 0 | S40: =IF(R40>1,R40-1,0) -> 0
B41: =HYPERLINK("#"&"'"&C41&"'"&"!A1","LINK") -> LINK | C41: =IF(PQ!B46="","",PQ!B46) -> C.1.4 | D41: =IF(PQ!C46="","",PQ!C46) -> Regularização de bota-fora com espalhamento e execução de hidrossemeadura | E41: =IF(PQ!E46="","",PQ!E46) -> m³ | F41: =IF(PQ!F46="","",PQ!F46) -> 2.6999987 | G41: =IF(PQ!G46="","",PQ!G46) -> 6357.64 | H41: {=INDIRECT($C41&"!E6")} -> 6357.638 | I41: {=INDIRECT($C41&"!E9")} -> 0 | J41: {=INDIRECT($C41&"!E5")} -> 6357.638 | K41: {=INDIRECT($C41&"!E7")} -> 0.002 | L41: {=INDIRECT($C41&"!E8")} -> 0 | M41: {=INDIRECT($C41&"!G6")} -> 17165.615 | N41: {=INDIRECT($C41&"!G9")} -> 0 | O41: {=INDIRECT($C41&"!G5")} -> 17165.615 | P41: {=INDIRECT($C41&"!G7")} -> 0.0053999975 | Q41: {=INDIRECT($C41&"!G8")} -> 0 | R41: =IF(ISERROR(J41/G41),0,J41/G41) -> 0.99999969 | S41: =IF(R41>1,R41-1,0) -> 0
B42: =HYPERLINK("#"&"'"&C42&"'"&"!A1","LINK") -> LINK | C42: =IF(PQ!B47="","",PQ!B47) -> C.1.5 | D42: =IF(PQ!C47="","",PQ!C47) -> Regularização de bota-fora | E42: =IF(PQ!E47="","",PQ!E47) -> m³ | F42: =IF(PQ!F47="","",PQ!F47) -> 2.3299998 | G42: =IF(PQ!G47="","",PQ!G47) -> 6357.64 | H42: {=INDIRECT($C42&"!E6")} -> 0 | I42: {=INDIRECT($C42&"!E9")} -> 0 | J42: {=INDIRECT($C42&"!E5")} -> 0 | K42: {=INDIRECT($C42&"!E7")} -> 6357.64 | L42: {=INDIRECT($C42&"!E8")} -> 0 | M42: {=INDIRECT($C42&"!G6")} -> 0 | N42: {=INDIRECT($C42&"!G9")} -> 0 | O42: {=INDIRECT($C42&"!G5")} -> 0 | P42: {=INDIRECT($C42&"!G7")} -> 14813.3 | Q42: {=INDIRECT($C42&"!G8")} -> 0 | R42: =IF(ISERROR(J42/G42),0,J42/G42) -> 0 | S42: =IF(R42>1,R42-1,0) -> 0
...

Sheet MUNICIPIOS
A1: RECOMPOSIÇÃO DE TALUDES - SINISTRO 297+500 - OESTE - RATEIO ISS
A2: CÓDIGO | B2: DESCRIÇÃO | C2: 24/09/2025 a 23/10/2025 | D2: GOVERNADOR VALADARES | F2: PERIQUITO | H2: NAQUE | J2: BELO HORIENTE | L2: SANTANA DO PARAÍSO | N2: IPATINGA | P2: CORONEL FABRICIANO | R2: TIMÓTEO | T2: JAGUARAÇU | V2: ANTÔNIO DIAS | X2: NOVA ERA | Z2: BELA VISTA DE MINAS | AB2: JOÃO MONLEVADE | AD2: SÃO GONÇALO DO RIO ABAIXO | AF2: BARÃO DE COCAIS | AH2: BOM JESUS DO AMPARO | AJ2: NOVA UNIÃO | AL2: CAETÉ | AN2: ACUMULADO
C4: Nº MEDIÇÃO 03 | D4: % | E4: R$ | F4: % | G4: R$ | H4: % | I4: R$ | J4: % | K4: R$ | L4: % | M4: R$ | N4: % | O4: R$ | P4: % | Q4: R$ | R4: % | S4: R$ | T4: % | U4: R$ | V4: % | W4: R$ | X4: % | Y4: R$ | Z4: % | AA4: R$ | AB4: % | AC4: R$ | AD4: % | AE4: R$ | AF4: % | AG4: R$ | AH4: % | AI4: R$ | AJ4: % | AK4: R$ | AL4: % | AM4: R$ | AN4: % | AO4: R$
A6: =PQ!B13 -> A. | B6: =PQ!C13 -> Custos Indiretos | C6: =RESUMO!N8 -> 0 | E6: =SUBTOTAL(9,E7:E9) -> 0 | G6: =SUBTOTAL(9,G7:G9) -> 0 | I6: =SUBTOTAL(9,I7:I9) -> 0 | K6: =SUBTOTAL(9,K7:K9) -> 0 | M6: =SUBTOTAL(9,M7:M9) -> 0 | O6: =SUBTOTAL(9,O7:O9) -> 0 | Q6: =SUBTOTAL(9,Q7:Q9) -> 0 | S6: =SUBTOTAL(9,S7:S9) -> 0 | U6: =SUBTOTAL(9,U7:U9) -> 0 | W6: =SUBTOTAL(9,W7:W9) -> 0 | Y6: =SUBTOTAL(9,Y7:Y9) -> 0 | AA6: =SUBTOTAL(9,AA7:AA9) -> 0 | AC6: =SUBTOTAL(9,AC7:AC9) -> 0 | AE6: =SUBTOTAL(9,AE7:AE9) -> 0 | AG6: =SUBTOTAL(9,AG7:AG9) -> 0 | AI6: =SUBTOTAL(9,AI7:AI9) -> 0 | AK6: =SUBTOTAL(9,AK7:AK9) -> 0 | AM6: =SUBTOTAL(9,AM7:AM9) -> 0 | AO6: =SUBTOTAL(9,AO7:AO9) -> 0
A7: =PQ!B14 -> A.1 | B7: =PQ!C14 -> Mobilização e desmobilização | C7: =RESUMO!N9 -> 0 | E7: =$C7*D7 -> 0 | G7: =$C7*F7 -> 0 | I7: =$C7*H7 -> 0 | K7: =$C7*J7 -> 0 | M7: =$C7*L7 -> 0 | O7: =$C7*N7 -> 0 | Q7: =$C7*P7 -> 0 | S7: =$C7*R7 -> 0 | U7: =$C7*T7 -> 0 | W7: =$C7*V7 -> 0 | Y7: =$C7*X7 -> 0 | AA7: =$C7*Z7 -> 0 | AC7: =$C7*AB7 -> 0 | AE7: =$C7*AD7 -> 0 | AG7: =$C7*AF7 -> 0 | AI7: =$C7*AH7 -> 0 | AK7: =$C7*AJ7 -> 0 | AM7: =$C7*AL7 -> 0 | AN7: =SUM(D7,F7,H7,J7,L7,N7,P7,R7,T7,V7,X7,Z7,AB7,AD7,AF7,AH7,AJ7,AL7) -> 0 | AO7: =$C7*AN7 -> 0
A8: =PQ!B15 -> A.2 | B8: =PQ!C15 -> Sinalização e desvio de tráfego | C8: =RESUMO!N10 -> 0 | E8: =$C8*D8 -> 0 | G8: =$C8*F8 -> 0 | I8: =$C8*H8 -> 0 | K8: =$C8*J8 -> 0 | M8: =$C8*L8 -> 0 | O8: =$C8*N8 -> 0 | Q8: =$C8*P8 -> 0 | S8: =$C8*R8 -> 0 | U8: =$C8*T8 -> 0 | W8: =$C8*V8 -> 0 | Y8: =$C8*X8 -> 0 | AA8: =$C8*Z8 -> 0 | AC8: =$C8*AB8 -> 0 | AE8: =$C8*AD8 -> 0 | AG8: =$C8*AF8 -> 0 | AI8: =$C8*AH8 -> 0 | AK8: =$C8*AJ8 -> 0 | AM8: =$C8*AL8 -> 0 | AN8: =SUM(D8,F8,H8,J8,L8,N8,P8,R8,T8,V8,X8,Z8,AB8,AD8,AF8,AH8,AJ8,AL8) -> 0 | AO8: =$C8*AN8 -> 0
A9: =PQ!B16 -> A.3 | B9: =PQ!C16 -> Administração local | C9: =RESUMO!N11 -> 0 | E9: =$C9*D9 -> 0 | G9: =$C9*F9 -> 0 | I9: =$C9*H9 -> 0 | K9: =$C9*J9 -> 0 | M9: =$C9*L9 -> 0 | O9: =$C9*N9 -> 0 | Q9: =$C9*P9 -> 0 | S9: =$C9*R9 -> 0 | U9: =$C9*T9 -> 0 | W9: =$C9*V9 -> 0 | Y9: =$C9*X9 -> 0 | AA9: =$C9*Z9 -> 0 | AC9: =$C9*AB9 -> 0 | AE9: =$C9*AD9 -> 0 | AG9: =$C9*AF9 -> 0 | AI9: =$C9*AH9 -> 0 | AK9: =$C9*AJ9 -> 0 | AM9: =$C9*AL9 -> 0 | AN9: =SUM(D9,F9,H9,J9,L9,N9,P9,R9,T9,V9,X9,Z9,AB9,AD9,AF9,AH9,AJ9,AL9) -> 0 | AO9: =$C9*AN9 -> 0
A10: =PQ!B17 -> B. | B10: =PQ!C17 -> Estabilização de Talude | C10: =RESUMO!N12 -> 1870605.8 | E10: =SUBTOTAL(9,E11:E33) -> 0 | G10: =SUBTOTAL(9,G11:G33) -> 0 | I10: =SUBTOTAL(9,I11:I33) -> 0 | K10: =SUBTOTAL(9,K11:K33) -> 0 | M10: =SUBTOTAL(9,M11:M33) -> 0 | O10: =SUBTOTAL(9,O11:O33) -> 0 | Q10: =SUBTOTAL(9,Q11:Q33) -> 0 | S10: =SUBTOTAL(9,S11:S33) -> 0 | U10: =SUBTOTAL(9,U11:U33) -> 0 | W10: =SUBTOTAL(9,W11:W33) -> 1870605.8 | Y10: =SUBTOTAL(9,Y11:Y33) -> 0 | AA10: =SUBTOTAL(9,AA11:AA33) -> 0 | AC10: =SUBTOTAL(9,AC11:AC33) -> 0 | AE10: =SUBTOTAL(9,AE11:AE33) -> 0 | AG10: =SUBTOTAL(9,AG11:AG33) -> 0 | AI10: =SUBTOTAL(9,AI11:AI33) -> 0 | AK10: =SUBTOTAL(9,AK11:AK33) -> 0 | AM10: =SUBTOTAL(9,AM11:AM33) -> 0 | AO10: =SUBTOTAL(9,AO11:AO33) -> 1870605.8
A11: =PQ!B18 -> B.1 | B11: =PQ!C18 -> Terraplenagem | C11: =RESUMO!N13 -> 877293.31 | E11: =SUBTOTAL(9,E12:E20) -> 0 | G11: =SUBTOTAL(9,G12:G20) -> 0 | I11: =SUBTOTAL(9,I12:I20) -> 0 | K11: =SUBTOTAL(9,K12:K20) -> 0 | M11: =SUBTOTAL(9,M12:M20) -> 0 | O11: =SUBTOTAL(9,O12:O20) -> 0 | Q11: =SUBTOTAL(9,Q12:Q20) -> 0 | S11: =SUBTOTAL(9,S12:S20) -> 0 | U11: =SUBTOTAL(9,U12:U20) -> 0 | W11: =SUBTOTAL(9,W12:W20) -> 877293.31 | Y11: =SUBTOTAL(9,Y12:Y20) -> 0 | AA11: =SUBTOTAL(9,AA12:AA20) -> 0 | AC11: =SUBTOTAL(9,AC12:AC20) -> 0 | AE11: =SUBTOTAL(9,AE12:AE20) -> 0 | AG11: =SUBTOTAL(9,AG12:AG20) -> 0 | AI11: =SUBTOTAL(9,AI12:AI20) -> 0 | AK11: =SUBTOTAL(9,AK12:AK20) -> 0 | AM11: =SUBTOTAL(9,AM12:AM20) -> 0 | AO11: =SUBTOTAL(9,AO12:AO20) -> 877293.31
A12: =PQ!B19 -> B.1.1 | B12: =PQ!C19 -> Escavação, carga e transporte de material de 1ª categoria - DMT de 800 a 1.000 m - caminho de serviço pavimentado - com escavadeira e caminhão basculante de 14 m³ | C12: =RESUMO!N14 -> 0 | E12: =$C12*D12 -> 0 | G12: =$C12*F12 -> 0 | I12: =$C12*H12 -> 0 | K12: =$C12*J12 -> 0 | M12: =$C12*L12 -> 0 | O12: =$C12*N12 -> 0 | Q12: =$C12*P12 -> 0 | S12: =$C12*R12 -> 0 | U12: =$C12*T12 -> 0 | W12: =$C12*V12 -> 0 | Y12: =$C12*X12 -> 0 | AA12: =$C12*Z12 -> 0 | AC12: =$C12*AB12 -> 0 | AE12: =$C12*AD12 -> 0 | AG12: =$C12*AF12 -> 0 | AI12: =$C12*AH12 -> 0 | AK12: =$C12*AJ12 -> 0 | AM12: =$C12*AL12 -> 0 | AN12: =SUM(D12,F12,H12,J12,L12,N12,P12,R12,T12,V12,X12,Z12,AB12,AD12,AF12,AH12,AJ12,AL12) -> 0 | AO12: =$C12*AN12 -> 0
A13: =PQ!B20 -> B.1.2 | B13: =PQ!C20 -> Escavação e carga de material de 1ª categoria - DMT acima de 3.000 m | C13: =RESUMO!N15 -> 97492.676 | E13: =$C13*D13 -> 0 | G13: =$C13*F13 -> 0 | I13: =$C13*H13 -> 0 | K13: =$C13*J13 -> 0 | M13: =$C13*L13 -> 0 | O13: =$C13*N13 -> 0 | Q13: =$C13*P13 -> 0 | S13: =$C13*R13 -> 0 | U13: =$C13*T13 -> 0 | V13: 1 | W13: =$C13*V13 -> 97492.676 | Y13: =$C13*X13 -> 0 | AA13: =$C13*Z13 -> 0 | AC13: =$C13*AB13 -> 0 | AE13: =$C13*AD13 -> 0 | AG13: =$C13*AF13 -> 0 | AI13: =$C13*AH13 -> 0 | AK13: =$C13*AJ13 -> 0 | AM13: =$C13*AL13 -> 0 | AN13: =SUM(D13,F13,H13,J13,L13,N13,P13,R13,T13,V13,X13,Z13,AB13,AD13,AF13,AH13,AJ13,AL13) -> 1 | AO13: =$C13*AN13 -> 97492.676
A14: =PQ!B21 -> B.1.3 | B14: =PQ!C21 -> Transporte com caminhão basculante de 10 m³ - rodovia pavimentada (DMT 5 Km) | C14: =RESUMO!N16 -> 48774.217 | E14: =$C14*D14 -> 0 | G14: =$C14*F14 -> 0 | I14: =$C14*H14 -> 0 | K14: =$C14*J14 -> 0 | M14: =$C14*L14 -> 0 | O14: =$C14*N14 -> 0 | Q14: =$C14*P14 -> 0 | S14: =$C14*R14 -> 0 | U14: =$C14*T14 -> 0 | V14: 1 | W14: =$C14*V14 -> 48774.217 | Y14: =$C14*X14 -> 0 | AA14: =$C14*Z14 -> 0 | AC14: =$C14*AB14 -> 0 | AE14: =$C14*AD14 -> 0 | AG14: =$C14*AF14 -> 0 | AI14: =$C14*AH14 -> 0 | AK14: =$C14*AJ14 -> 0 | AM14: =$C14*AL14 -> 0 | AN14: =SUM(D14,F14,H14,J14,L14,N14,P14,R14,T14,V14,X14,Z14,AB14,AD14,AF14,AH14,AJ14,AL14) -> 1 | AO14: =$C14*AN14 -> 48774.217
A15: =PQ!B22 -> B.1.4 | B15: =PQ!C22 -> Regularização de bota-fora com espalhamento e execução de hidrossemeadura | C15: =RESUMO!N17 -> 0 | E15: =$C15*D15 -> 0 | G15: =$C15*F15 -> 0 | I15: =$C15*H15 -> 0 | K15: =$C15*J15 -> 0 | M15: =$C15*L15 -> 0 | O15: =$C15*N15 -> 0 | Q15: =$C15*P15 -> 0 | S15: =$C15*R15 -> 0 | U15: =$C15*T15 -> 0 | W15: =$C15*V15 -> 0 | Y15: =$C15*X15 -> 0 | AA15: =$C15*Z15 -> 0 | AC15: =$C15*AB15 -> 0 | AE15: =$C15*AD15 -> 0 | AG15: =$C15*AF15 -> 0 | AI15: =$C15*AH15 -> 0 | AK15: =$C15*AJ15 -> 0 | AM15: =$C15*AL15 -> 0 | AN15: =SUM(D15,F15,H15,J15,L15,N15,P15,R15,T15,V15,X15,Z15,AB15,AD15,AF15,AH15,AJ15,AL15) -> 0 | AO15: =$C15*AN15 -> 0
A16: =PQ!B23 -> B.1.5 | B16: =PQ!C23 -> Royaltie de bota-fora | C16: =RESUMO!N18 -> 0 | E16: =$C16*D16 -> 0 | G16: =$C16*F16 -> 0 | I16: =$C16*H16 -> 0 | K16: =$C16*J16 -> 0 | M16: =$C16*L16 -> 0 | O16: =$C16*N16 -> 0 | Q16: =$C16*P16 -> 0 | S16: =$C16*R16 -> 0 | U16: =$C16*T16 -> 0 | W16: =$C16*V16 -> 0 | Y16: =$C16*X16 -> 0 | AA16: =$C16*Z16 -> 0 | AC16: =$C16*AB16 -> 0 | AE16: =$C16*AD16 -> 0 | AG16: =$C16*AF16 -> 0 | AI16: =$C16*AH16 -> 0 | AK16: =$C16*AJ16 -> 0 | AM16: =$C16*AL16 -> 0 | AN16: =SUM(D16,F16,H16,J16,L16,N16,P16,R16,T16,V16,X16,Z16,AB16,AD16,AF16,AH16,AJ16,AL16) -> 0 | AO16: =$C16*AN16 -> 0
A17: =PQ!B24 -> B.1.6 | B17: =PQ!C24 -> Desmatamento, destocamento, limpeza de área e estocagem do material de limpeza com árvores de diâmetro até 0,15 m | C17: =RESUMO!N19 -> 18277.002 | E17: =$C17*D17 -> 0 | G17: =$C17*F17 -> 0 | I17: =$C17*H17 -> 0 | K17: =$C17*J17 -> 0 | M17: =$C17*L17 -> 0 | O17: =$C17*N17 -> 0 | Q17: =$C17*P17 -> 0 | S17: =$C17*R17 -> 0 | U17: =$C17*T17 -> 0 | V17: 1 | W17: =$C17*V17 -> 18277.002 | Y17: =$C17*X17 -> 0 | AA17: =$C17*Z17 -> 0 | AC17: =$C17*AB17 -> 0 | AE17: =$C17*AD17 -> 0 | AG17: =$C17*AF17 -> 0 | AI17: =$C17*AH17 -> 0 | AK17: =$C17*AJ17 -> 0 | AM17: =$C17*AL17 -> 0 | AN17: =SUM(D17,F17,H17,J17,L17,N17,P17,R17,T17,V17,X17,Z17,AB17,AD17,AF17,AH17,AJ17,AL17) -> 1 | AO17: =$C17*AN17 -> 18277.002
A18: =PQ!B25 -> B.1.7 | B18: =PQ!C25 -> Escavação, carga e transporte de material de 1ª categoria - DMT de 1.400 a 1.600 m - caminho de serviço pavimentado - com escavadeira e caminhão basculante de 14 m³ | C18: =RESUMO!N20 -> 695707.05 | E18: =$C18*D18 -> 0 | G18: =$C18*F18 -> 0 | I18: =$C18*H18 -> 0 | K18: =$C18*J18 -> 0 | M18: =$C18*L18 -> 0 | O18: =$C18*N18 -> 0 | Q18: =$C18*P18 -> 0 | S18: =$C18*R18 -> 0 | U18: =$C18*T18 -> 0 | V18: 1 | W18: =$C18*V18 -> 695707.05 | Y18: =$C18*X18 -> 0 | AA18: =$C18*Z18 -> 0 | AC18: =$C18*AB18 -> 0 | AE18: =$C18*AD18 -> 0 | AG18: =$C18*AF18 -> 0 | AI18: =$C18*AH18 -> 0 | AK18: =$C18*AJ18 -> 0 | AM18: =$C18*AL18 -> 0 | AN18: =SUM(D18,F18,H18,J18,L18,N18,P18,R18,T18,V18,X18,Z18,AB18,AD18,AF18,AH18,AJ18,AL18) -> 1 | AO18: =$C18*AN18 -> 695707.05
A19: =PQ!B26 -> B.1.8 | B19: =PQ!C26 -> Escavação e carga de material de 2ª categoria - DMT acima de 3.000 m | C19: =RESUMO!N21 -> 2722.6105 | E19: =$C19*D19 -> 0 | G19: =$C19*F19 -> 0 | I19: =$C19*H19 -> 0 | K19: =$C19*J19 -> 0 | M19: =$C19*L19 -> 0 | O19: =$C19*N19 -> 0 | Q19: =$C19*P19 -> 0 | S19: =$C19*R19 -> 0 | U19: =$C19*T19 -> 0 | V19: 1 | W19: =$C19*V19 -> 2722.6105 | Y19: =$C19*X19 -> 0 | AA19: =$C19*Z19 -> 0 | AC19: =$C19*AB19 -> 0 | AE19: =$C19*AD19 -> 0 | AG19: =$C19*AF19 -> 0 | AI19: =$C19*AH19 -> 0 | AK19: =$C19*AJ19 -> 0 | AM19: =$C19*AL19 -> 0 | AN19: =SUM(D19,F19,H19,J19,L19,N19,P19,R19,T19,V19,X19,Z19,AB19,AD19,AF19,AH19,AJ19,AL19) -> 1 | AO19: =$C19*AN19 -> 2722.6105
A20: =PQ!B27 -> B.1.9 | B20: =PQ!C27 -> Regularização de bota-fora | C20: =RESUMO!N22 -> 14319.751 | E20: =$C20*D20 -> 0 | G20: =$C20*F20 -> 0 | I20: =$C20*H20 -> 0 | K20: =$C20*J20 -> 0 | M20: =$C20*L20 -> 0 | O20: =$C20*N20 -> 0 | Q20: =$C20*P20 -> 0 | S20: =$C20*R20 -> 0 | U20: =$C20*T20 -> 0 | V20: 1 | W20: =$C20*V20 -> 14319.751 | Y20: =$C20*X20 -> 0 | AA20: =$C20*Z20 -> 0 | AC20: =$C20*AB20 -> 0 | AE20: =$C20*AD20 -> 0 | AG20: =$C20*AF20 -> 0 | AI20: =$C20*AH20 -> 0 | AK20: =$C20*AJ20 -> 0 | AM20: =$C20*AL20 -> 0 | AN20: =SUM(D20,F20,H20,J20,L20,N20,P20,R20,T20,V20,X20,Z20,AB20,AD20,AF20,AH20,AJ20,AL20) -> 1 | AO20: =$C20*AN20 -> 14319.751
A21: =PQ!B28 -> B.2 | B21: =PQ!C28 -> Drenagem e OACs | C21: =RESUMO!N23 -> 372089.89 | E21: =SUBTOTAL(9,E22:E30) -> 0 | G21: =SUBTOTAL(9,G22:G30) -> 0 | I21: =SUBTOTAL(9,I22:I30) -> 0 | K21: =SUBTOTAL(9,K22:K30) -> 0 | M21: =SUBTOTAL(9,M22:M30) -> 0 | O21: =SUBTOTAL(9,O22:O30) -> 0 | Q21: =SUBTOTAL(9,Q22:Q30) -> 0 | S21: =SUBTOTAL(9,S22:S30) -> 0 | U21: =SUBTOTAL(9,U22:U30) -> 0 | W21: =SUBTOTAL(9,W22:W30) -> 372089.89 | Y21: =SUBTOTAL(9,Y22:Y30) -> 0 | AA21: =SUBTOTAL(9,AA22:AA30) -> 0 | AC21: =SUBTOTAL(9,AC22:AC30) -> 0 | AE21: =SUBTOTAL(9,AE22:AE30) -> 0 | AG21: =SUBTOTAL(9,AG22:AG30) -> 0 | AI21: =SUBTOTAL(9,AI22:AI30) -> 0 | AK21: =SUBTOTAL(9,AK22:AK30) -> 0 | AM21: =SUBTOTAL(9,AM22:AM30) -> 0 | AO21: =SUBTOTAL(9,AO22:AO30) -> 372089.89
A22: =PQ!B29 -> B.2.1 | B22: =PQ!C29 -> Demolição de dispositivos de drenagem | C22: =RESUMO!N24 -> 0 | E22: =$C22*D22 -> 0 | G22: =$C22*F22 -> 0 | I22: =$C22*H22 -> 0 | K22: =$C22*J22 -> 0 | M22: =$C22*L22 -> 0 | O22: =$C22*N22 -> 0 | Q22: =$C22*P22 -> 0 | S22: =$C22*R22 -> 0 | U22: =$C22*T22 -> 0 | W22: =$C22*V22 -> 0 | Y22: =$C22*X22 -> 0 | AA22: =$C22*Z22 -> 0 | AC22: =$C22*AB22 -> 0 | AE22: =$C22*AD22 -> 0 | AG22: =$C22*AF22 -> 0 | AI22: =$C22*AH22 -> 0 | AK22: =$C22*AJ22 -> 0 | AM22: =$C22*AL22 -> 0 | AN22: =SUM(D22,F22,H22,J22,L22,N22,P22,R22,T22,V22,X22,Z22,AB22,AD22,AF22,AH22,AJ22,AL22) -> 0 | AO22: =$C22*AN22 -> 0
